Here is the list of inputs:
OPTIONS jobs 3
OPTIONS queues 3
OPTIONS allotments for queue  2 is 100
OPTIONS quantum length for queue  2 is  10
OPTIONS allotments for queue  1 is 100
OPTIONS quantum length for queue  1 is  10
OPTIONS allotments for queue  0 is 100
OPTIONS quantum length for queue  0 is  10
OPTIONS boost 500
OPTIONS ioTime 5
OPTIONS stayAfterIO False
OPTIONS iobump False


For each job, three defining characteristics are given:
  startTime : at what time does the job enter the system
  runTime   : the total CPU time needed by the job to finish
  ioFreq    : every ioFreq time units, the job issues an I/O
              (the I/O takes ioTime units to complete)

Job List:
  Job  0: startTime   0 - runTime 180 - ioFreq   0
  Job  1: startTime   0 - runTime 200 - ioFreq   0
  Job  2: startTime   0 - runTime 500 - ioFreq   0


Execution Trace:

[ time 0 ] JOB BEGINS by JOB 0
[ time 0 ] JOB BEGINS by JOB 1
[ time 0 ] JOB BEGINS by JOB 2
[ time 0 ] Run JOB 0 at PRIORITY 2 [ TICKS 9 ALLOT 100 TIME 179 (of 180) ]
[ time 1 ] Run JOB 0 at PRIORITY 2 [ TICKS 8 ALLOT 100 TIME 178 (of 180) ]
[ time 2 ] Run JOB 0 at PRIORITY 2 [ TICKS 7 ALLOT 100 TIME 177 (of 180) ]
[ time 3 ] Run JOB 0 at PRIORITY 2 [ TICKS 6 ALLOT 100 TIME 176 (of 180) ]
[ time 4 ] Run JOB 0 at PRIORITY 2 [ TICKS 5 ALLOT 100 TIME 175 (of 180) ]
[ time 5 ] Run JOB 0 at PRIORITY 2 [ TICKS 4 ALLOT 100 TIME 174 (of 180) ]
[ time 6 ] Run JOB 0 at PRIORITY 2 [ TICKS 3 ALLOT 100 TIME 173 (of 180) ]
[ time 7 ] Run JOB 0 at PRIORITY 2 [ TICKS 2 ALLOT 100 TIME 172 (of 180) ]
[ time 8 ] Run JOB 0 at PRIORITY 2 [ TICKS 1 ALLOT 100 TIME 171 (of 180) ]
[ time 9 ] Run JOB 0 at PRIORITY 2 [ TICKS 0 ALLOT 100 TIME 170 (of 180) ]
[ time 10 ] Run JOB 1 at PRIORITY 2 [ TICKS 9 ALLOT 100 TIME 199 (of 200) ]
[ time 11 ] Run JOB 1 at PRIORITY 2 [ TICKS 8 ALLOT 100 TIME 198 (of 200) ]
[ time 12 ] Run JOB 1 at PRIORITY 2 [ TICKS 7 ALLOT 100 TIME 197 (of 200) ]
[ time 13 ] Run JOB 1 at PRIORITY 2 [ TICKS 6 ALLOT 100 TIME 196 (of 200) ]
[ time 14 ] Run JOB 1 at PRIORITY 2 [ TICKS 5 ALLOT 100 TIME 195 (of 200) ]
[ time 15 ] Run JOB 1 at PRIORITY 2 [ TICKS 4 ALLOT 100 TIME 194 (of 200) ]
[ time 16 ] Run JOB 1 at PRIORITY 2 [ TICKS 3 ALLOT 100 TIME 193 (of 200) ]
[ time 17 ] Run JOB 1 at PRIORITY 2 [ TICKS 2 ALLOT 100 TIME 192 (of 200) ]
[ time 18 ] Run JOB 1 at PRIORITY 2 [ TICKS 1 ALLOT 100 TIME 191 (of 200) ]
[ time 19 ] Run JOB 1 at PRIORITY 2 [ TICKS 0 ALLOT 100 TIME 190 (of 200) ]
[ time 20 ] Run JOB 2 at PRIORITY 2 [ TICKS 9 ALLOT 100 TIME 499 (of 500) ]
[ time 21 ] Run JOB 2 at PRIORITY 2 [ TICKS 8 ALLOT 100 TIME 498 (of 500) ]
[ time 22 ] Run JOB 2 at PRIORITY 2 [ TICKS 7 ALLOT 100 TIME 497 (of 500) ]
[ time 23 ] Run JOB 2 at PRIORITY 2 [ TICKS 6 ALLOT 100 TIME 496 (of 500) ]
[ time 24 ] Run JOB 2 at PRIORITY 2 [ TICKS 5 ALLOT 100 TIME 495 (of 500) ]
[ time 25 ] Run JOB 2 at PRIORITY 2 [ TICKS 4 ALLOT 100 TIME 494 (of 500) ]
[ time 26 ] Run JOB 2 at PRIORITY 2 [ TICKS 3 ALLOT 100 TIME 493 (of 500) ]
[ time 27 ] Run JOB 2 at PRIORITY 2 [ TICKS 2 ALLOT 100 TIME 492 (of 500) ]
[ time 28 ] Run JOB 2 at PRIORITY 2 [ TICKS 1 ALLOT 100 TIME 491 (of 500) ]
[ time 29 ] Run JOB 2 at PRIORITY 2 [ TICKS 0 ALLOT 100 TIME 490 (of 500) ]
[ time 30 ] Run JOB 0 at PRIORITY 2 [ TICKS 9 ALLOT 99 TIME 169 (of 180) ]
[ time 31 ] Run JOB 0 at PRIORITY 2 [ TICKS 8 ALLOT 99 TIME 168 (of 180) ]
[ time 32 ] Run JOB 0 at PRIORITY 2 [ TICKS 7 ALLOT 99 TIME 167 (of 180) ]
[ time 33 ] Run JOB 0 at PRIORITY 2 [ TICKS 6 ALLOT 99 TIME 166 (of 180) ]
[ time 34 ] Run JOB 0 at PRIORITY 2 [ TICKS 5 ALLOT 99 TIME 165 (of 180) ]
[ time 35 ] Run JOB 0 at PRIORITY 2 [ TICKS 4 ALLOT 99 TIME 164 (of 180) ]
[ time 36 ] Run JOB 0 at PRIORITY 2 [ TICKS 3 ALLOT 99 TIME 163 (of 180) ]
[ time 37 ] Run JOB 0 at PRIORITY 2 [ TICKS 2 ALLOT 99 TIME 162 (of 180) ]
[ time 38 ] Run JOB 0 at PRIORITY 2 [ TICKS 1 ALLOT 99 TIME 161 (of 180) ]
[ time 39 ] Run JOB 0 at PRIORITY 2 [ TICKS 0 ALLOT 99 TIME 160 (of 180) ]
[ time 40 ] Run JOB 1 at PRIORITY 2 [ TICKS 9 ALLOT 99 TIME 189 (of 200) ]
[ time 41 ] Run JOB 1 at PRIORITY 2 [ TICKS 8 ALLOT 99 TIME 188 (of 200) ]
[ time 42 ] Run JOB 1 at PRIORITY 2 [ TICKS 7 ALLOT 99 TIME 187 (of 200) ]
[ time 43 ] Run JOB 1 at PRIORITY 2 [ TICKS 6 ALLOT 99 TIME 186 (of 200) ]
[ time 44 ] Run JOB 1 at PRIORITY 2 [ TICKS 5 ALLOT 99 TIME 185 (of 200) ]
[ time 45 ] Run JOB 1 at PRIORITY 2 [ TICKS 4 ALLOT 99 TIME 184 (of 200) ]
[ time 46 ] Run JOB 1 at PRIORITY 2 [ TICKS 3 ALLOT 99 TIME 183 (of 200) ]
[ time 47 ] Run JOB 1 at PRIORITY 2 [ TICKS 2 ALLOT 99 TIME 182 (of 200) ]
[ time 48 ] Run JOB 1 at PRIORITY 2 [ TICKS 1 ALLOT 99 TIME 181 (of 200) ]
[ time 49 ] Run JOB 1 at PRIORITY 2 [ TICKS 0 ALLOT 99 TIME 180 (of 200) ]
[ time 50 ] Run JOB 2 at PRIORITY 2 [ TICKS 9 ALLOT 99 TIME 489 (of 500) ]
[ time 51 ] Run JOB 2 at PRIORITY 2 [ TICKS 8 ALLOT 99 TIME 488 (of 500) ]
[ time 52 ] Run JOB 2 at PRIORITY 2 [ TICKS 7 ALLOT 99 TIME 487 (of 500) ]
[ time 53 ] Run JOB 2 at PRIORITY 2 [ TICKS 6 ALLOT 99 TIME 486 (of 500) ]
[ time 54 ] Run JOB 2 at PRIORITY 2 [ TICKS 5 ALLOT 99 TIME 485 (of 500) ]
[ time 55 ] Run JOB 2 at PRIORITY 2 [ TICKS 4 ALLOT 99 TIME 484 (of 500) ]
[ time 56 ] Run JOB 2 at PRIORITY 2 [ TICKS 3 ALLOT 99 TIME 483 (of 500) ]
[ time 57 ] Run JOB 2 at PRIORITY 2 [ TICKS 2 ALLOT 99 TIME 482 (of 500) ]
[ time 58 ] Run JOB 2 at PRIORITY 2 [ TICKS 1 ALLOT 99 TIME 481 (of 500) ]
[ time 59 ] Run JOB 2 at PRIORITY 2 [ TICKS 0 ALLOT 99 TIME 480 (of 500) ]
[ time 60 ] Run JOB 0 at PRIORITY 2 [ TICKS 9 ALLOT 98 TIME 159 (of 180) ]
[ time 61 ] Run JOB 0 at PRIORITY 2 [ TICKS 8 ALLOT 98 TIME 158 (of 180) ]
[ time 62 ] Run JOB 0 at PRIORITY 2 [ TICKS 7 ALLOT 98 TIME 157 (of 180) ]
[ time 63 ] Run JOB 0 at PRIORITY 2 [ TICKS 6 ALLOT 98 TIME 156 (of 180) ]
[ time 64 ] Run JOB 0 at PRIORITY 2 [ TICKS 5 ALLOT 98 TIME 155 (of 180) ]
[ time 65 ] Run JOB 0 at PRIORITY 2 [ TICKS 4 ALLOT 98 TIME 154 (of 180) ]
[ time 66 ] Run JOB 0 at PRIORITY 2 [ TICKS 3 ALLOT 98 TIME 153 (of 180) ]
[ time 67 ] Run JOB 0 at PRIORITY 2 [ TICKS 2 ALLOT 98 TIME 152 (of 180) ]
[ time 68 ] Run JOB 0 at PRIORITY 2 [ TICKS 1 ALLOT 98 TIME 151 (of 180) ]
[ time 69 ] Run JOB 0 at PRIORITY 2 [ TICKS 0 ALLOT 98 TIME 150 (of 180) ]
[ time 70 ] Run JOB 1 at PRIORITY 2 [ TICKS 9 ALLOT 98 TIME 179 (of 200) ]
[ time 71 ] Run JOB 1 at PRIORITY 2 [ TICKS 8 ALLOT 98 TIME 178 (of 200) ]
[ time 72 ] Run JOB 1 at PRIORITY 2 [ TICKS 7 ALLOT 98 TIME 177 (of 200) ]
[ time 73 ] Run JOB 1 at PRIORITY 2 [ TICKS 6 ALLOT 98 TIME 176 (of 200) ]
[ time 74 ] Run JOB 1 at PRIORITY 2 [ TICKS 5 ALLOT 98 TIME 175 (of 200) ]
[ time 75 ] Run JOB 1 at PRIORITY 2 [ TICKS 4 ALLOT 98 TIME 174 (of 200) ]
[ time 76 ] Run JOB 1 at PRIORITY 2 [ TICKS 3 ALLOT 98 TIME 173 (of 200) ]
[ time 77 ] Run JOB 1 at PRIORITY 2 [ TICKS 2 ALLOT 98 TIME 172 (of 200) ]
[ time 78 ] Run JOB 1 at PRIORITY 2 [ TICKS 1 ALLOT 98 TIME 171 (of 200) ]
[ time 79 ] Run JOB 1 at PRIORITY 2 [ TICKS 0 ALLOT 98 TIME 170 (of 200) ]
[ time 80 ] Run JOB 2 at PRIORITY 2 [ TICKS 9 ALLOT 98 TIME 479 (of 500) ]
[ time 81 ] Run JOB 2 at PRIORITY 2 [ TICKS 8 ALLOT 98 TIME 478 (of 500) ]
[ time 82 ] Run JOB 2 at PRIORITY 2 [ TICKS 7 ALLOT 98 TIME 477 (of 500) ]
[ time 83 ] Run JOB 2 at PRIORITY 2 [ TICKS 6 ALLOT 98 TIME 476 (of 500) ]
[ time 84 ] Run JOB 2 at PRIORITY 2 [ TICKS 5 ALLOT 98 TIME 475 (of 500) ]
[ time 85 ] Run JOB 2 at PRIORITY 2 [ TICKS 4 ALLOT 98 TIME 474 (of 500) ]
[ time 86 ] Run JOB 2 at PRIORITY 2 [ TICKS 3 ALLOT 98 TIME 473 (of 500) ]
[ time 87 ] Run JOB 2 at PRIORITY 2 [ TICKS 2 ALLOT 98 TIME 472 (of 500) ]
[ time 88 ] Run JOB 2 at PRIORITY 2 [ TICKS 1 ALLOT 98 TIME 471 (of 500) ]
[ time 89 ] Run JOB 2 at PRIORITY 2 [ TICKS 0 ALLOT 98 TIME 470 (of 500) ]
[ time 90 ] Run JOB 0 at PRIORITY 2 [ TICKS 9 ALLOT 97 TIME 149 (of 180) ]
[ time 91 ] Run JOB 0 at PRIORITY 2 [ TICKS 8 ALLOT 97 TIME 148 (of 180) ]
[ time 92 ] Run JOB 0 at PRIORITY 2 [ TICKS 7 ALLOT 97 TIME 147 (of 180) ]
[ time 93 ] Run JOB 0 at PRIORITY 2 [ TICKS 6 ALLOT 97 TIME 146 (of 180) ]
[ time 94 ] Run JOB 0 at PRIORITY 2 [ TICKS 5 ALLOT 97 TIME 145 (of 180) ]
[ time 95 ] Run JOB 0 at PRIORITY 2 [ TICKS 4 ALLOT 97 TIME 144 (of 180) ]
[ time 96 ] Run JOB 0 at PRIORITY 2 [ TICKS 3 ALLOT 97 TIME 143 (of 180) ]
[ time 97 ] Run JOB 0 at PRIORITY 2 [ TICKS 2 ALLOT 97 TIME 142 (of 180) ]
[ time 98 ] Run JOB 0 at PRIORITY 2 [ TICKS 1 ALLOT 97 TIME 141 (of 180) ]
[ time 99 ] Run JOB 0 at PRIORITY 2 [ TICKS 0 ALLOT 97 TIME 140 (of 180) ]
[ time 100 ] Run JOB 1 at PRIORITY 2 [ TICKS 9 ALLOT 97 TIME 169 (of 200) ]
[ time 101 ] Run JOB 1 at PRIORITY 2 [ TICKS 8 ALLOT 97 TIME 168 (of 200) ]
[ time 102 ] Run JOB 1 at PRIORITY 2 [ TICKS 7 ALLOT 97 TIME 167 (of 200) ]
[ time 103 ] Run JOB 1 at PRIORITY 2 [ TICKS 6 ALLOT 97 TIME 166 (of 200) ]
[ time 104 ] Run JOB 1 at PRIORITY 2 [ TICKS 5 ALLOT 97 TIME 165 (of 200) ]
[ time 105 ] Run JOB 1 at PRIORITY 2 [ TICKS 4 ALLOT 97 TIME 164 (of 200) ]
[ time 106 ] Run JOB 1 at PRIORITY 2 [ TICKS 3 ALLOT 97 TIME 163 (of 200) ]
[ time 107 ] Run JOB 1 at PRIORITY 2 [ TICKS 2 ALLOT 97 TIME 162 (of 200) ]
[ time 108 ] Run JOB 1 at PRIORITY 2 [ TICKS 1 ALLOT 97 TIME 161 (of 200) ]
[ time 109 ] Run JOB 1 at PRIORITY 2 [ TICKS 0 ALLOT 97 TIME 160 (of 200) ]
[ time 110 ] Run JOB 2 at PRIORITY 2 [ TICKS 9 ALLOT 97 TIME 469 (of 500) ]
[ time 111 ] Run JOB 2 at PRIORITY 2 [ TICKS 8 ALLOT 97 TIME 468 (of 500) ]
[ time 112 ] Run JOB 2 at PRIORITY 2 [ TICKS 7 ALLOT 97 TIME 467 (of 500) ]
[ time 113 ] Run JOB 2 at PRIORITY 2 [ TICKS 6 ALLOT 97 TIME 466 (of 500) ]
[ time 114 ] Run JOB 2 at PRIORITY 2 [ TICKS 5 ALLOT 97 TIME 465 (of 500) ]
[ time 115 ] Run JOB 2 at PRIORITY 2 [ TICKS 4 ALLOT 97 TIME 464 (of 500) ]
[ time 116 ] Run JOB 2 at PRIORITY 2 [ TICKS 3 ALLOT 97 TIME 463 (of 500) ]
[ time 117 ] Run JOB 2 at PRIORITY 2 [ TICKS 2 ALLOT 97 TIME 462 (of 500) ]
[ time 118 ] Run JOB 2 at PRIORITY 2 [ TICKS 1 ALLOT 97 TIME 461 (of 500) ]
[ time 119 ] Run JOB 2 at PRIORITY 2 [ TICKS 0 ALLOT 97 TIME 460 (of 500) ]
[ time 120 ] Run JOB 0 at PRIORITY 2 [ TICKS 9 ALLOT 96 TIME 139 (of 180) ]
[ time 121 ] Run JOB 0 at PRIORITY 2 [ TICKS 8 ALLOT 96 TIME 138 (of 180) ]
[ time 122 ] Run JOB 0 at PRIORITY 2 [ TICKS 7 ALLOT 96 TIME 137 (of 180) ]
[ time 123 ] Run JOB 0 at PRIORITY 2 [ TICKS 6 ALLOT 96 TIME 136 (of 180) ]
[ time 124 ] Run JOB 0 at PRIORITY 2 [ TICKS 5 ALLOT 96 TIME 135 (of 180) ]
[ time 125 ] Run JOB 0 at PRIORITY 2 [ TICKS 4 ALLOT 96 TIME 134 (of 180) ]
[ time 126 ] Run JOB 0 at PRIORITY 2 [ TICKS 3 ALLOT 96 TIME 133 (of 180) ]
[ time 127 ] Run JOB 0 at PRIORITY 2 [ TICKS 2 ALLOT 96 TIME 132 (of 180) ]
[ time 128 ] Run JOB 0 at PRIORITY 2 [ TICKS 1 ALLOT 96 TIME 131 (of 180) ]
[ time 129 ] Run JOB 0 at PRIORITY 2 [ TICKS 0 ALLOT 96 TIME 130 (of 180) ]
[ time 130 ] Run JOB 1 at PRIORITY 2 [ TICKS 9 ALLOT 96 TIME 159 (of 200) ]
[ time 131 ] Run JOB 1 at PRIORITY 2 [ TICKS 8 ALLOT 96 TIME 158 (of 200) ]
[ time 132 ] Run JOB 1 at PRIORITY 2 [ TICKS 7 ALLOT 96 TIME 157 (of 200) ]
[ time 133 ] Run JOB 1 at PRIORITY 2 [ TICKS 6 ALLOT 96 TIME 156 (of 200) ]
[ time 134 ] Run JOB 1 at PRIORITY 2 [ TICKS 5 ALLOT 96 TIME 155 (of 200) ]
[ time 135 ] Run JOB 1 at PRIORITY 2 [ TICKS 4 ALLOT 96 TIME 154 (of 200) ]
[ time 136 ] Run JOB 1 at PRIORITY 2 [ TICKS 3 ALLOT 96 TIME 153 (of 200) ]
[ time 137 ] Run JOB 1 at PRIORITY 2 [ TICKS 2 ALLOT 96 TIME 152 (of 200) ]
[ time 138 ] Run JOB 1 at PRIORITY 2 [ TICKS 1 ALLOT 96 TIME 151 (of 200) ]
[ time 139 ] Run JOB 1 at PRIORITY 2 [ TICKS 0 ALLOT 96 TIME 150 (of 200) ]
[ time 140 ] Run JOB 2 at PRIORITY 2 [ TICKS 9 ALLOT 96 TIME 459 (of 500) ]
[ time 141 ] Run JOB 2 at PRIORITY 2 [ TICKS 8 ALLOT 96 TIME 458 (of 500) ]
[ time 142 ] Run JOB 2 at PRIORITY 2 [ TICKS 7 ALLOT 96 TIME 457 (of 500) ]
[ time 143 ] Run JOB 2 at PRIORITY 2 [ TICKS 6 ALLOT 96 TIME 456 (of 500) ]
[ time 144 ] Run JOB 2 at PRIORITY 2 [ TICKS 5 ALLOT 96 TIME 455 (of 500) ]
[ time 145 ] Run JOB 2 at PRIORITY 2 [ TICKS 4 ALLOT 96 TIME 454 (of 500) ]
[ time 146 ] Run JOB 2 at PRIORITY 2 [ TICKS 3 ALLOT 96 TIME 453 (of 500) ]
[ time 147 ] Run JOB 2 at PRIORITY 2 [ TICKS 2 ALLOT 96 TIME 452 (of 500) ]
[ time 148 ] Run JOB 2 at PRIORITY 2 [ TICKS 1 ALLOT 96 TIME 451 (of 500) ]
[ time 149 ] Run JOB 2 at PRIORITY 2 [ TICKS 0 ALLOT 96 TIME 450 (of 500) ]
[ time 150 ] Run JOB 0 at PRIORITY 2 [ TICKS 9 ALLOT 95 TIME 129 (of 180) ]
[ time 151 ] Run JOB 0 at PRIORITY 2 [ TICKS 8 ALLOT 95 TIME 128 (of 180) ]
[ time 152 ] Run JOB 0 at PRIORITY 2 [ TICKS 7 ALLOT 95 TIME 127 (of 180) ]
[ time 153 ] Run JOB 0 at PRIORITY 2 [ TICKS 6 ALLOT 95 TIME 126 (of 180) ]
[ time 154 ] Run JOB 0 at PRIORITY 2 [ TICKS 5 ALLOT 95 TIME 125 (of 180) ]
[ time 155 ] Run JOB 0 at PRIORITY 2 [ TICKS 4 ALLOT 95 TIME 124 (of 180) ]
[ time 156 ] Run JOB 0 at PRIORITY 2 [ TICKS 3 ALLOT 95 TIME 123 (of 180) ]
[ time 157 ] Run JOB 0 at PRIORITY 2 [ TICKS 2 ALLOT 95 TIME 122 (of 180) ]
[ time 158 ] Run JOB 0 at PRIORITY 2 [ TICKS 1 ALLOT 95 TIME 121 (of 180) ]
[ time 159 ] Run JOB 0 at PRIORITY 2 [ TICKS 0 ALLOT 95 TIME 120 (of 180) ]
[ time 160 ] Run JOB 1 at PRIORITY 2 [ TICKS 9 ALLOT 95 TIME 149 (of 200) ]
[ time 161 ] Run JOB 1 at PRIORITY 2 [ TICKS 8 ALLOT 95 TIME 148 (of 200) ]
[ time 162 ] Run JOB 1 at PRIORITY 2 [ TICKS 7 ALLOT 95 TIME 147 (of 200) ]
[ time 163 ] Run JOB 1 at PRIORITY 2 [ TICKS 6 ALLOT 95 TIME 146 (of 200) ]
[ time 164 ] Run JOB 1 at PRIORITY 2 [ TICKS 5 ALLOT 95 TIME 145 (of 200) ]
[ time 165 ] Run JOB 1 at PRIORITY 2 [ TICKS 4 ALLOT 95 TIME 144 (of 200) ]
[ time 166 ] Run JOB 1 at PRIORITY 2 [ TICKS 3 ALLOT 95 TIME 143 (of 200) ]
[ time 167 ] Run JOB 1 at PRIORITY 2 [ TICKS 2 ALLOT 95 TIME 142 (of 200) ]
[ time 168 ] Run JOB 1 at PRIORITY 2 [ TICKS 1 ALLOT 95 TIME 141 (of 200) ]
[ time 169 ] Run JOB 1 at PRIORITY 2 [ TICKS 0 ALLOT 95 TIME 140 (of 200) ]
[ time 170 ] Run JOB 2 at PRIORITY 2 [ TICKS 9 ALLOT 95 TIME 449 (of 500) ]
[ time 171 ] Run JOB 2 at PRIORITY 2 [ TICKS 8 ALLOT 95 TIME 448 (of 500) ]
[ time 172 ] Run JOB 2 at PRIORITY 2 [ TICKS 7 ALLOT 95 TIME 447 (of 500) ]
[ time 173 ] Run JOB 2 at PRIORITY 2 [ TICKS 6 ALLOT 95 TIME 446 (of 500) ]
[ time 174 ] Run JOB 2 at PRIORITY 2 [ TICKS 5 ALLOT 95 TIME 445 (of 500) ]
[ time 175 ] Run JOB 2 at PRIORITY 2 [ TICKS 4 ALLOT 95 TIME 444 (of 500) ]
[ time 176 ] Run JOB 2 at PRIORITY 2 [ TICKS 3 ALLOT 95 TIME 443 (of 500) ]
[ time 177 ] Run JOB 2 at PRIORITY 2 [ TICKS 2 ALLOT 95 TIME 442 (of 500) ]
[ time 178 ] Run JOB 2 at PRIORITY 2 [ TICKS 1 ALLOT 95 TIME 441 (of 500) ]
[ time 179 ] Run JOB 2 at PRIORITY 2 [ TICKS 0 ALLOT 95 TIME 440 (of 500) ]
[ time 180 ] Run JOB 0 at PRIORITY 2 [ TICKS 9 ALLOT 94 TIME 119 (of 180) ]
[ time 181 ] Run JOB 0 at PRIORITY 2 [ TICKS 8 ALLOT 94 TIME 118 (of 180) ]
[ time 182 ] Run JOB 0 at PRIORITY 2 [ TICKS 7 ALLOT 94 TIME 117 (of 180) ]
[ time 183 ] Run JOB 0 at PRIORITY 2 [ TICKS 6 ALLOT 94 TIME 116 (of 180) ]
[ time 184 ] Run JOB 0 at PRIORITY 2 [ TICKS 5 ALLOT 94 TIME 115 (of 180) ]
[ time 185 ] Run JOB 0 at PRIORITY 2 [ TICKS 4 ALLOT 94 TIME 114 (of 180) ]
[ time 186 ] Run JOB 0 at PRIORITY 2 [ TICKS 3 ALLOT 94 TIME 113 (of 180) ]
[ time 187 ] Run JOB 0 at PRIORITY 2 [ TICKS 2 ALLOT 94 TIME 112 (of 180) ]
[ time 188 ] Run JOB 0 at PRIORITY 2 [ TICKS 1 ALLOT 94 TIME 111 (of 180) ]
[ time 189 ] Run JOB 0 at PRIORITY 2 [ TICKS 0 ALLOT 94 TIME 110 (of 180) ]
[ time 190 ] Run JOB 1 at PRIORITY 2 [ TICKS 9 ALLOT 94 TIME 139 (of 200) ]
[ time 191 ] Run JOB 1 at PRIORITY 2 [ TICKS 8 ALLOT 94 TIME 138 (of 200) ]
[ time 192 ] Run JOB 1 at PRIORITY 2 [ TICKS 7 ALLOT 94 TIME 137 (of 200) ]
[ time 193 ] Run JOB 1 at PRIORITY 2 [ TICKS 6 ALLOT 94 TIME 136 (of 200) ]
[ time 194 ] Run JOB 1 at PRIORITY 2 [ TICKS 5 ALLOT 94 TIME 135 (of 200) ]
[ time 195 ] Run JOB 1 at PRIORITY 2 [ TICKS 4 ALLOT 94 TIME 134 (of 200) ]
[ time 196 ] Run JOB 1 at PRIORITY 2 [ TICKS 3 ALLOT 94 TIME 133 (of 200) ]
[ time 197 ] Run JOB 1 at PRIORITY 2 [ TICKS 2 ALLOT 94 TIME 132 (of 200) ]
[ time 198 ] Run JOB 1 at PRIORITY 2 [ TICKS 1 ALLOT 94 TIME 131 (of 200) ]
[ time 199 ] Run JOB 1 at PRIORITY 2 [ TICKS 0 ALLOT 94 TIME 130 (of 200) ]
[ time 200 ] Run JOB 2 at PRIORITY 2 [ TICKS 9 ALLOT 94 TIME 439 (of 500) ]
[ time 201 ] Run JOB 2 at PRIORITY 2 [ TICKS 8 ALLOT 94 TIME 438 (of 500) ]
[ time 202 ] Run JOB 2 at PRIORITY 2 [ TICKS 7 ALLOT 94 TIME 437 (of 500) ]
[ time 203 ] Run JOB 2 at PRIORITY 2 [ TICKS 6 ALLOT 94 TIME 436 (of 500) ]
[ time 204 ] Run JOB 2 at PRIORITY 2 [ TICKS 5 ALLOT 94 TIME 435 (of 500) ]
[ time 205 ] Run JOB 2 at PRIORITY 2 [ TICKS 4 ALLOT 94 TIME 434 (of 500) ]
[ time 206 ] Run JOB 2 at PRIORITY 2 [ TICKS 3 ALLOT 94 TIME 433 (of 500) ]
[ time 207 ] Run JOB 2 at PRIORITY 2 [ TICKS 2 ALLOT 94 TIME 432 (of 500) ]
[ time 208 ] Run JOB 2 at PRIORITY 2 [ TICKS 1 ALLOT 94 TIME 431 (of 500) ]
[ time 209 ] Run JOB 2 at PRIORITY 2 [ TICKS 0 ALLOT 94 TIME 430 (of 500) ]
[ time 210 ] Run JOB 0 at PRIORITY 2 [ TICKS 9 ALLOT 93 TIME 109 (of 180) ]
[ time 211 ] Run JOB 0 at PRIORITY 2 [ TICKS 8 ALLOT 93 TIME 108 (of 180) ]
[ time 212 ] Run JOB 0 at PRIORITY 2 [ TICKS 7 ALLOT 93 TIME 107 (of 180) ]
[ time 213 ] Run JOB 0 at PRIORITY 2 [ TICKS 6 ALLOT 93 TIME 106 (of 180) ]
[ time 214 ] Run JOB 0 at PRIORITY 2 [ TICKS 5 ALLOT 93 TIME 105 (of 180) ]
[ time 215 ] Run JOB 0 at PRIORITY 2 [ TICKS 4 ALLOT 93 TIME 104 (of 180) ]
[ time 216 ] Run JOB 0 at PRIORITY 2 [ TICKS 3 ALLOT 93 TIME 103 (of 180) ]
[ time 217 ] Run JOB 0 at PRIORITY 2 [ TICKS 2 ALLOT 93 TIME 102 (of 180) ]
[ time 218 ] Run JOB 0 at PRIORITY 2 [ TICKS 1 ALLOT 93 TIME 101 (of 180) ]
[ time 219 ] Run JOB 0 at PRIORITY 2 [ TICKS 0 ALLOT 93 TIME 100 (of 180) ]
[ time 220 ] Run JOB 1 at PRIORITY 2 [ TICKS 9 ALLOT 93 TIME 129 (of 200) ]
[ time 221 ] Run JOB 1 at PRIORITY 2 [ TICKS 8 ALLOT 93 TIME 128 (of 200) ]
[ time 222 ] Run JOB 1 at PRIORITY 2 [ TICKS 7 ALLOT 93 TIME 127 (of 200) ]
[ time 223 ] Run JOB 1 at PRIORITY 2 [ TICKS 6 ALLOT 93 TIME 126 (of 200) ]
[ time 224 ] Run JOB 1 at PRIORITY 2 [ TICKS 5 ALLOT 93 TIME 125 (of 200) ]
[ time 225 ] Run JOB 1 at PRIORITY 2 [ TICKS 4 ALLOT 93 TIME 124 (of 200) ]
[ time 226 ] Run JOB 1 at PRIORITY 2 [ TICKS 3 ALLOT 93 TIME 123 (of 200) ]
[ time 227 ] Run JOB 1 at PRIORITY 2 [ TICKS 2 ALLOT 93 TIME 122 (of 200) ]
[ time 228 ] Run JOB 1 at PRIORITY 2 [ TICKS 1 ALLOT 93 TIME 121 (of 200) ]
[ time 229 ] Run JOB 1 at PRIORITY 2 [ TICKS 0 ALLOT 93 TIME 120 (of 200) ]
[ time 230 ] Run JOB 2 at PRIORITY 2 [ TICKS 9 ALLOT 93 TIME 429 (of 500) ]
[ time 231 ] Run JOB 2 at PRIORITY 2 [ TICKS 8 ALLOT 93 TIME 428 (of 500) ]
[ time 232 ] Run JOB 2 at PRIORITY 2 [ TICKS 7 ALLOT 93 TIME 427 (of 500) ]
[ time 233 ] Run JOB 2 at PRIORITY 2 [ TICKS 6 ALLOT 93 TIME 426 (of 500) ]
[ time 234 ] Run JOB 2 at PRIORITY 2 [ TICKS 5 ALLOT 93 TIME 425 (of 500) ]
[ time 235 ] Run JOB 2 at PRIORITY 2 [ TICKS 4 ALLOT 93 TIME 424 (of 500) ]
[ time 236 ] Run JOB 2 at PRIORITY 2 [ TICKS 3 ALLOT 93 TIME 423 (of 500) ]
[ time 237 ] Run JOB 2 at PRIORITY 2 [ TICKS 2 ALLOT 93 TIME 422 (of 500) ]
[ time 238 ] Run JOB 2 at PRIORITY 2 [ TICKS 1 ALLOT 93 TIME 421 (of 500) ]
[ time 239 ] Run JOB 2 at PRIORITY 2 [ TICKS 0 ALLOT 93 TIME 420 (of 500) ]
[ time 240 ] Run JOB 0 at PRIORITY 2 [ TICKS 9 ALLOT 92 TIME 99 (of 180) ]
[ time 241 ] Run JOB 0 at PRIORITY 2 [ TICKS 8 ALLOT 92 TIME 98 (of 180) ]
[ time 242 ] Run JOB 0 at PRIORITY 2 [ TICKS 7 ALLOT 92 TIME 97 (of 180) ]
[ time 243 ] Run JOB 0 at PRIORITY 2 [ TICKS 6 ALLOT 92 TIME 96 (of 180) ]
[ time 244 ] Run JOB 0 at PRIORITY 2 [ TICKS 5 ALLOT 92 TIME 95 (of 180) ]
[ time 245 ] Run JOB 0 at PRIORITY 2 [ TICKS 4 ALLOT 92 TIME 94 (of 180) ]
[ time 246 ] Run JOB 0 at PRIORITY 2 [ TICKS 3 ALLOT 92 TIME 93 (of 180) ]
[ time 247 ] Run JOB 0 at PRIORITY 2 [ TICKS 2 ALLOT 92 TIME 92 (of 180) ]
[ time 248 ] Run JOB 0 at PRIORITY 2 [ TICKS 1 ALLOT 92 TIME 91 (of 180) ]
[ time 249 ] Run JOB 0 at PRIORITY 2 [ TICKS 0 ALLOT 92 TIME 90 (of 180) ]
[ time 250 ] Run JOB 1 at PRIORITY 2 [ TICKS 9 ALLOT 92 TIME 119 (of 200) ]
[ time 251 ] Run JOB 1 at PRIORITY 2 [ TICKS 8 ALLOT 92 TIME 118 (of 200) ]
[ time 252 ] Run JOB 1 at PRIORITY 2 [ TICKS 7 ALLOT 92 TIME 117 (of 200) ]
[ time 253 ] Run JOB 1 at PRIORITY 2 [ TICKS 6 ALLOT 92 TIME 116 (of 200) ]
[ time 254 ] Run JOB 1 at PRIORITY 2 [ TICKS 5 ALLOT 92 TIME 115 (of 200) ]
[ time 255 ] Run JOB 1 at PRIORITY 2 [ TICKS 4 ALLOT 92 TIME 114 (of 200) ]
[ time 256 ] Run JOB 1 at PRIORITY 2 [ TICKS 3 ALLOT 92 TIME 113 (of 200) ]
[ time 257 ] Run JOB 1 at PRIORITY 2 [ TICKS 2 ALLOT 92 TIME 112 (of 200) ]
[ time 258 ] Run JOB 1 at PRIORITY 2 [ TICKS 1 ALLOT 92 TIME 111 (of 200) ]
[ time 259 ] Run JOB 1 at PRIORITY 2 [ TICKS 0 ALLOT 92 TIME 110 (of 200) ]
[ time 260 ] Run JOB 2 at PRIORITY 2 [ TICKS 9 ALLOT 92 TIME 419 (of 500) ]
[ time 261 ] Run JOB 2 at PRIORITY 2 [ TICKS 8 ALLOT 92 TIME 418 (of 500) ]
[ time 262 ] Run JOB 2 at PRIORITY 2 [ TICKS 7 ALLOT 92 TIME 417 (of 500) ]
[ time 263 ] Run JOB 2 at PRIORITY 2 [ TICKS 6 ALLOT 92 TIME 416 (of 500) ]
[ time 264 ] Run JOB 2 at PRIORITY 2 [ TICKS 5 ALLOT 92 TIME 415 (of 500) ]
[ time 265 ] Run JOB 2 at PRIORITY 2 [ TICKS 4 ALLOT 92 TIME 414 (of 500) ]
[ time 266 ] Run JOB 2 at PRIORITY 2 [ TICKS 3 ALLOT 92 TIME 413 (of 500) ]
[ time 267 ] Run JOB 2 at PRIORITY 2 [ TICKS 2 ALLOT 92 TIME 412 (of 500) ]
[ time 268 ] Run JOB 2 at PRIORITY 2 [ TICKS 1 ALLOT 92 TIME 411 (of 500) ]
[ time 269 ] Run JOB 2 at PRIORITY 2 [ TICKS 0 ALLOT 92 TIME 410 (of 500) ]
[ time 270 ] Run JOB 0 at PRIORITY 2 [ TICKS 9 ALLOT 91 TIME 89 (of 180) ]
[ time 271 ] Run JOB 0 at PRIORITY 2 [ TICKS 8 ALLOT 91 TIME 88 (of 180) ]
[ time 272 ] Run JOB 0 at PRIORITY 2 [ TICKS 7 ALLOT 91 TIME 87 (of 180) ]
[ time 273 ] Run JOB 0 at PRIORITY 2 [ TICKS 6 ALLOT 91 TIME 86 (of 180) ]
[ time 274 ] Run JOB 0 at PRIORITY 2 [ TICKS 5 ALLOT 91 TIME 85 (of 180) ]
[ time 275 ] Run JOB 0 at PRIORITY 2 [ TICKS 4 ALLOT 91 TIME 84 (of 180) ]
[ time 276 ] Run JOB 0 at PRIORITY 2 [ TICKS 3 ALLOT 91 TIME 83 (of 180) ]
[ time 277 ] Run JOB 0 at PRIORITY 2 [ TICKS 2 ALLOT 91 TIME 82 (of 180) ]
[ time 278 ] Run JOB 0 at PRIORITY 2 [ TICKS 1 ALLOT 91 TIME 81 (of 180) ]
[ time 279 ] Run JOB 0 at PRIORITY 2 [ TICKS 0 ALLOT 91 TIME 80 (of 180) ]
[ time 280 ] Run JOB 1 at PRIORITY 2 [ TICKS 9 ALLOT 91 TIME 109 (of 200) ]
[ time 281 ] Run JOB 1 at PRIORITY 2 [ TICKS 8 ALLOT 91 TIME 108 (of 200) ]
[ time 282 ] Run JOB 1 at PRIORITY 2 [ TICKS 7 ALLOT 91 TIME 107 (of 200) ]
[ time 283 ] Run JOB 1 at PRIORITY 2 [ TICKS 6 ALLOT 91 TIME 106 (of 200) ]
[ time 284 ] Run JOB 1 at PRIORITY 2 [ TICKS 5 ALLOT 91 TIME 105 (of 200) ]
[ time 285 ] Run JOB 1 at PRIORITY 2 [ TICKS 4 ALLOT 91 TIME 104 (of 200) ]
[ time 286 ] Run JOB 1 at PRIORITY 2 [ TICKS 3 ALLOT 91 TIME 103 (of 200) ]
[ time 287 ] Run JOB 1 at PRIORITY 2 [ TICKS 2 ALLOT 91 TIME 102 (of 200) ]
[ time 288 ] Run JOB 1 at PRIORITY 2 [ TICKS 1 ALLOT 91 TIME 101 (of 200) ]
[ time 289 ] Run JOB 1 at PRIORITY 2 [ TICKS 0 ALLOT 91 TIME 100 (of 200) ]
[ time 290 ] Run JOB 2 at PRIORITY 2 [ TICKS 9 ALLOT 91 TIME 409 (of 500) ]
[ time 291 ] Run JOB 2 at PRIORITY 2 [ TICKS 8 ALLOT 91 TIME 408 (of 500) ]
[ time 292 ] Run JOB 2 at PRIORITY 2 [ TICKS 7 ALLOT 91 TIME 407 (of 500) ]
[ time 293 ] Run JOB 2 at PRIORITY 2 [ TICKS 6 ALLOT 91 TIME 406 (of 500) ]
[ time 294 ] Run JOB 2 at PRIORITY 2 [ TICKS 5 ALLOT 91 TIME 405 (of 500) ]
[ time 295 ] Run JOB 2 at PRIORITY 2 [ TICKS 4 ALLOT 91 TIME 404 (of 500) ]
[ time 296 ] Run JOB 2 at PRIORITY 2 [ TICKS 3 ALLOT 91 TIME 403 (of 500) ]
[ time 297 ] Run JOB 2 at PRIORITY 2 [ TICKS 2 ALLOT 91 TIME 402 (of 500) ]
[ time 298 ] Run JOB 2 at PRIORITY 2 [ TICKS 1 ALLOT 91 TIME 401 (of 500) ]
[ time 299 ] Run JOB 2 at PRIORITY 2 [ TICKS 0 ALLOT 91 TIME 400 (of 500) ]
[ time 300 ] Run JOB 0 at PRIORITY 2 [ TICKS 9 ALLOT 90 TIME 79 (of 180) ]
[ time 301 ] Run JOB 0 at PRIORITY 2 [ TICKS 8 ALLOT 90 TIME 78 (of 180) ]
[ time 302 ] Run JOB 0 at PRIORITY 2 [ TICKS 7 ALLOT 90 TIME 77 (of 180) ]
[ time 303 ] Run JOB 0 at PRIORITY 2 [ TICKS 6 ALLOT 90 TIME 76 (of 180) ]
[ time 304 ] Run JOB 0 at PRIORITY 2 [ TICKS 5 ALLOT 90 TIME 75 (of 180) ]
[ time 305 ] Run JOB 0 at PRIORITY 2 [ TICKS 4 ALLOT 90 TIME 74 (of 180) ]
[ time 306 ] Run JOB 0 at PRIORITY 2 [ TICKS 3 ALLOT 90 TIME 73 (of 180) ]
[ time 307 ] Run JOB 0 at PRIORITY 2 [ TICKS 2 ALLOT 90 TIME 72 (of 180) ]
[ time 308 ] Run JOB 0 at PRIORITY 2 [ TICKS 1 ALLOT 90 TIME 71 (of 180) ]
[ time 309 ] Run JOB 0 at PRIORITY 2 [ TICKS 0 ALLOT 90 TIME 70 (of 180) ]
[ time 310 ] Run JOB 1 at PRIORITY 2 [ TICKS 9 ALLOT 90 TIME 99 (of 200) ]
[ time 311 ] Run JOB 1 at PRIORITY 2 [ TICKS 8 ALLOT 90 TIME 98 (of 200) ]
[ time 312 ] Run JOB 1 at PRIORITY 2 [ TICKS 7 ALLOT 90 TIME 97 (of 200) ]
[ time 313 ] Run JOB 1 at PRIORITY 2 [ TICKS 6 ALLOT 90 TIME 96 (of 200) ]
[ time 314 ] Run JOB 1 at PRIORITY 2 [ TICKS 5 ALLOT 90 TIME 95 (of 200) ]
[ time 315 ] Run JOB 1 at PRIORITY 2 [ TICKS 4 ALLOT 90 TIME 94 (of 200) ]
[ time 316 ] Run JOB 1 at PRIORITY 2 [ TICKS 3 ALLOT 90 TIME 93 (of 200) ]
[ time 317 ] Run JOB 1 at PRIORITY 2 [ TICKS 2 ALLOT 90 TIME 92 (of 200) ]
[ time 318 ] Run JOB 1 at PRIORITY 2 [ TICKS 1 ALLOT 90 TIME 91 (of 200) ]
[ time 319 ] Run JOB 1 at PRIORITY 2 [ TICKS 0 ALLOT 90 TIME 90 (of 200) ]
[ time 320 ] Run JOB 2 at PRIORITY 2 [ TICKS 9 ALLOT 90 TIME 399 (of 500) ]
[ time 321 ] Run JOB 2 at PRIORITY 2 [ TICKS 8 ALLOT 90 TIME 398 (of 500) ]
[ time 322 ] Run JOB 2 at PRIORITY 2 [ TICKS 7 ALLOT 90 TIME 397 (of 500) ]
[ time 323 ] Run JOB 2 at PRIORITY 2 [ TICKS 6 ALLOT 90 TIME 396 (of 500) ]
[ time 324 ] Run JOB 2 at PRIORITY 2 [ TICKS 5 ALLOT 90 TIME 395 (of 500) ]
[ time 325 ] Run JOB 2 at PRIORITY 2 [ TICKS 4 ALLOT 90 TIME 394 (of 500) ]
[ time 326 ] Run JOB 2 at PRIORITY 2 [ TICKS 3 ALLOT 90 TIME 393 (of 500) ]
[ time 327 ] Run JOB 2 at PRIORITY 2 [ TICKS 2 ALLOT 90 TIME 392 (of 500) ]
[ time 328 ] Run JOB 2 at PRIORITY 2 [ TICKS 1 ALLOT 90 TIME 391 (of 500) ]
[ time 329 ] Run JOB 2 at PRIORITY 2 [ TICKS 0 ALLOT 90 TIME 390 (of 500) ]
[ time 330 ] Run JOB 0 at PRIORITY 2 [ TICKS 9 ALLOT 89 TIME 69 (of 180) ]
[ time 331 ] Run JOB 0 at PRIORITY 2 [ TICKS 8 ALLOT 89 TIME 68 (of 180) ]
[ time 332 ] Run JOB 0 at PRIORITY 2 [ TICKS 7 ALLOT 89 TIME 67 (of 180) ]
[ time 333 ] Run JOB 0 at PRIORITY 2 [ TICKS 6 ALLOT 89 TIME 66 (of 180) ]
[ time 334 ] Run JOB 0 at PRIORITY 2 [ TICKS 5 ALLOT 89 TIME 65 (of 180) ]
[ time 335 ] Run JOB 0 at PRIORITY 2 [ TICKS 4 ALLOT 89 TIME 64 (of 180) ]
[ time 336 ] Run JOB 0 at PRIORITY 2 [ TICKS 3 ALLOT 89 TIME 63 (of 180) ]
[ time 337 ] Run JOB 0 at PRIORITY 2 [ TICKS 2 ALLOT 89 TIME 62 (of 180) ]
[ time 338 ] Run JOB 0 at PRIORITY 2 [ TICKS 1 ALLOT 89 TIME 61 (of 180) ]
[ time 339 ] Run JOB 0 at PRIORITY 2 [ TICKS 0 ALLOT 89 TIME 60 (of 180) ]
[ time 340 ] Run JOB 1 at PRIORITY 2 [ TICKS 9 ALLOT 89 TIME 89 (of 200) ]
[ time 341 ] Run JOB 1 at PRIORITY 2 [ TICKS 8 ALLOT 89 TIME 88 (of 200) ]
[ time 342 ] Run JOB 1 at PRIORITY 2 [ TICKS 7 ALLOT 89 TIME 87 (of 200) ]
[ time 343 ] Run JOB 1 at PRIORITY 2 [ TICKS 6 ALLOT 89 TIME 86 (of 200) ]
[ time 344 ] Run JOB 1 at PRIORITY 2 [ TICKS 5 ALLOT 89 TIME 85 (of 200) ]
[ time 345 ] Run JOB 1 at PRIORITY 2 [ TICKS 4 ALLOT 89 TIME 84 (of 200) ]
[ time 346 ] Run JOB 1 at PRIORITY 2 [ TICKS 3 ALLOT 89 TIME 83 (of 200) ]
[ time 347 ] Run JOB 1 at PRIORITY 2 [ TICKS 2 ALLOT 89 TIME 82 (of 200) ]
[ time 348 ] Run JOB 1 at PRIORITY 2 [ TICKS 1 ALLOT 89 TIME 81 (of 200) ]
[ time 349 ] Run JOB 1 at PRIORITY 2 [ TICKS 0 ALLOT 89 TIME 80 (of 200) ]
[ time 350 ] Run JOB 2 at PRIORITY 2 [ TICKS 9 ALLOT 89 TIME 389 (of 500) ]
[ time 351 ] Run JOB 2 at PRIORITY 2 [ TICKS 8 ALLOT 89 TIME 388 (of 500) ]
[ time 352 ] Run JOB 2 at PRIORITY 2 [ TICKS 7 ALLOT 89 TIME 387 (of 500) ]
[ time 353 ] Run JOB 2 at PRIORITY 2 [ TICKS 6 ALLOT 89 TIME 386 (of 500) ]
[ time 354 ] Run JOB 2 at PRIORITY 2 [ TICKS 5 ALLOT 89 TIME 385 (of 500) ]
[ time 355 ] Run JOB 2 at PRIORITY 2 [ TICKS 4 ALLOT 89 TIME 384 (of 500) ]
[ time 356 ] Run JOB 2 at PRIORITY 2 [ TICKS 3 ALLOT 89 TIME 383 (of 500) ]
[ time 357 ] Run JOB 2 at PRIORITY 2 [ TICKS 2 ALLOT 89 TIME 382 (of 500) ]
[ time 358 ] Run JOB 2 at PRIORITY 2 [ TICKS 1 ALLOT 89 TIME 381 (of 500) ]
[ time 359 ] Run JOB 2 at PRIORITY 2 [ TICKS 0 ALLOT 89 TIME 380 (of 500) ]
[ time 360 ] Run JOB 0 at PRIORITY 2 [ TICKS 9 ALLOT 88 TIME 59 (of 180) ]
[ time 361 ] Run JOB 0 at PRIORITY 2 [ TICKS 8 ALLOT 88 TIME 58 (of 180) ]
[ time 362 ] Run JOB 0 at PRIORITY 2 [ TICKS 7 ALLOT 88 TIME 57 (of 180) ]
[ time 363 ] Run JOB 0 at PRIORITY 2 [ TICKS 6 ALLOT 88 TIME 56 (of 180) ]
[ time 364 ] Run JOB 0 at PRIORITY 2 [ TICKS 5 ALLOT 88 TIME 55 (of 180) ]
[ time 365 ] Run JOB 0 at PRIORITY 2 [ TICKS 4 ALLOT 88 TIME 54 (of 180) ]
[ time 366 ] Run JOB 0 at PRIORITY 2 [ TICKS 3 ALLOT 88 TIME 53 (of 180) ]
[ time 367 ] Run JOB 0 at PRIORITY 2 [ TICKS 2 ALLOT 88 TIME 52 (of 180) ]
[ time 368 ] Run JOB 0 at PRIORITY 2 [ TICKS 1 ALLOT 88 TIME 51 (of 180) ]
[ time 369 ] Run JOB 0 at PRIORITY 2 [ TICKS 0 ALLOT 88 TIME 50 (of 180) ]
[ time 370 ] Run JOB 1 at PRIORITY 2 [ TICKS 9 ALLOT 88 TIME 79 (of 200) ]
[ time 371 ] Run JOB 1 at PRIORITY 2 [ TICKS 8 ALLOT 88 TIME 78 (of 200) ]
[ time 372 ] Run JOB 1 at PRIORITY 2 [ TICKS 7 ALLOT 88 TIME 77 (of 200) ]
[ time 373 ] Run JOB 1 at PRIORITY 2 [ TICKS 6 ALLOT 88 TIME 76 (of 200) ]
[ time 374 ] Run JOB 1 at PRIORITY 2 [ TICKS 5 ALLOT 88 TIME 75 (of 200) ]
[ time 375 ] Run JOB 1 at PRIORITY 2 [ TICKS 4 ALLOT 88 TIME 74 (of 200) ]
[ time 376 ] Run JOB 1 at PRIORITY 2 [ TICKS 3 ALLOT 88 TIME 73 (of 200) ]
[ time 377 ] Run JOB 1 at PRIORITY 2 [ TICKS 2 ALLOT 88 TIME 72 (of 200) ]
[ time 378 ] Run JOB 1 at PRIORITY 2 [ TICKS 1 ALLOT 88 TIME 71 (of 200) ]
[ time 379 ] Run JOB 1 at PRIORITY 2 [ TICKS 0 ALLOT 88 TIME 70 (of 200) ]
[ time 380 ] Run JOB 2 at PRIORITY 2 [ TICKS 9 ALLOT 88 TIME 379 (of 500) ]
[ time 381 ] Run JOB 2 at PRIORITY 2 [ TICKS 8 ALLOT 88 TIME 378 (of 500) ]
[ time 382 ] Run JOB 2 at PRIORITY 2 [ TICKS 7 ALLOT 88 TIME 377 (of 500) ]
[ time 383 ] Run JOB 2 at PRIORITY 2 [ TICKS 6 ALLOT 88 TIME 376 (of 500) ]
[ time 384 ] Run JOB 2 at PRIORITY 2 [ TICKS 5 ALLOT 88 TIME 375 (of 500) ]
[ time 385 ] Run JOB 2 at PRIORITY 2 [ TICKS 4 ALLOT 88 TIME 374 (of 500) ]
[ time 386 ] Run JOB 2 at PRIORITY 2 [ TICKS 3 ALLOT 88 TIME 373 (of 500) ]
[ time 387 ] Run JOB 2 at PRIORITY 2 [ TICKS 2 ALLOT 88 TIME 372 (of 500) ]
[ time 388 ] Run JOB 2 at PRIORITY 2 [ TICKS 1 ALLOT 88 TIME 371 (of 500) ]
[ time 389 ] Run JOB 2 at PRIORITY 2 [ TICKS 0 ALLOT 88 TIME 370 (of 500) ]
[ time 390 ] Run JOB 0 at PRIORITY 2 [ TICKS 9 ALLOT 87 TIME 49 (of 180) ]
[ time 391 ] Run JOB 0 at PRIORITY 2 [ TICKS 8 ALLOT 87 TIME 48 (of 180) ]
[ time 392 ] Run JOB 0 at PRIORITY 2 [ TICKS 7 ALLOT 87 TIME 47 (of 180) ]
[ time 393 ] Run JOB 0 at PRIORITY 2 [ TICKS 6 ALLOT 87 TIME 46 (of 180) ]
[ time 394 ] Run JOB 0 at PRIORITY 2 [ TICKS 5 ALLOT 87 TIME 45 (of 180) ]
[ time 395 ] Run JOB 0 at PRIORITY 2 [ TICKS 4 ALLOT 87 TIME 44 (of 180) ]
[ time 396 ] Run JOB 0 at PRIORITY 2 [ TICKS 3 ALLOT 87 TIME 43 (of 180) ]
[ time 397 ] Run JOB 0 at PRIORITY 2 [ TICKS 2 ALLOT 87 TIME 42 (of 180) ]
[ time 398 ] Run JOB 0 at PRIORITY 2 [ TICKS 1 ALLOT 87 TIME 41 (of 180) ]
[ time 399 ] Run JOB 0 at PRIORITY 2 [ TICKS 0 ALLOT 87 TIME 40 (of 180) ]
[ time 400 ] Run JOB 1 at PRIORITY 2 [ TICKS 9 ALLOT 87 TIME 69 (of 200) ]
[ time 401 ] Run JOB 1 at PRIORITY 2 [ TICKS 8 ALLOT 87 TIME 68 (of 200) ]
[ time 402 ] Run JOB 1 at PRIORITY 2 [ TICKS 7 ALLOT 87 TIME 67 (of 200) ]
[ time 403 ] Run JOB 1 at PRIORITY 2 [ TICKS 6 ALLOT 87 TIME 66 (of 200) ]
[ time 404 ] Run JOB 1 at PRIORITY 2 [ TICKS 5 ALLOT 87 TIME 65 (of 200) ]
[ time 405 ] Run JOB 1 at PRIORITY 2 [ TICKS 4 ALLOT 87 TIME 64 (of 200) ]
[ time 406 ] Run JOB 1 at PRIORITY 2 [ TICKS 3 ALLOT 87 TIME 63 (of 200) ]
[ time 407 ] Run JOB 1 at PRIORITY 2 [ TICKS 2 ALLOT 87 TIME 62 (of 200) ]
[ time 408 ] Run JOB 1 at PRIORITY 2 [ TICKS 1 ALLOT 87 TIME 61 (of 200) ]
[ time 409 ] Run JOB 1 at PRIORITY 2 [ TICKS 0 ALLOT 87 TIME 60 (of 200) ]
[ time 410 ] Run JOB 2 at PRIORITY 2 [ TICKS 9 ALLOT 87 TIME 369 (of 500) ]
[ time 411 ] Run JOB 2 at PRIORITY 2 [ TICKS 8 ALLOT 87 TIME 368 (of 500) ]
[ time 412 ] Run JOB 2 at PRIORITY 2 [ TICKS 7 ALLOT 87 TIME 367 (of 500) ]
[ time 413 ] Run JOB 2 at PRIORITY 2 [ TICKS 6 ALLOT 87 TIME 366 (of 500) ]
[ time 414 ] Run JOB 2 at PRIORITY 2 [ TICKS 5 ALLOT 87 TIME 365 (of 500) ]
[ time 415 ] Run JOB 2 at PRIORITY 2 [ TICKS 4 ALLOT 87 TIME 364 (of 500) ]
[ time 416 ] Run JOB 2 at PRIORITY 2 [ TICKS 3 ALLOT 87 TIME 363 (of 500) ]
[ time 417 ] Run JOB 2 at PRIORITY 2 [ TICKS 2 ALLOT 87 TIME 362 (of 500) ]
[ time 418 ] Run JOB 2 at PRIORITY 2 [ TICKS 1 ALLOT 87 TIME 361 (of 500) ]
[ time 419 ] Run JOB 2 at PRIORITY 2 [ TICKS 0 ALLOT 87 TIME 360 (of 500) ]
[ time 420 ] Run JOB 0 at PRIORITY 2 [ TICKS 9 ALLOT 86 TIME 39 (of 180) ]
[ time 421 ] Run JOB 0 at PRIORITY 2 [ TICKS 8 ALLOT 86 TIME 38 (of 180) ]
[ time 422 ] Run JOB 0 at PRIORITY 2 [ TICKS 7 ALLOT 86 TIME 37 (of 180) ]
[ time 423 ] Run JOB 0 at PRIORITY 2 [ TICKS 6 ALLOT 86 TIME 36 (of 180) ]
[ time 424 ] Run JOB 0 at PRIORITY 2 [ TICKS 5 ALLOT 86 TIME 35 (of 180) ]
[ time 425 ] Run JOB 0 at PRIORITY 2 [ TICKS 4 ALLOT 86 TIME 34 (of 180) ]
[ time 426 ] Run JOB 0 at PRIORITY 2 [ TICKS 3 ALLOT 86 TIME 33 (of 180) ]
[ time 427 ] Run JOB 0 at PRIORITY 2 [ TICKS 2 ALLOT 86 TIME 32 (of 180) ]
[ time 428 ] Run JOB 0 at PRIORITY 2 [ TICKS 1 ALLOT 86 TIME 31 (of 180) ]
[ time 429 ] Run JOB 0 at PRIORITY 2 [ TICKS 0 ALLOT 86 TIME 30 (of 180) ]
[ time 430 ] Run JOB 1 at PRIORITY 2 [ TICKS 9 ALLOT 86 TIME 59 (of 200) ]
[ time 431 ] Run JOB 1 at PRIORITY 2 [ TICKS 8 ALLOT 86 TIME 58 (of 200) ]
[ time 432 ] Run JOB 1 at PRIORITY 2 [ TICKS 7 ALLOT 86 TIME 57 (of 200) ]
[ time 433 ] Run JOB 1 at PRIORITY 2 [ TICKS 6 ALLOT 86 TIME 56 (of 200) ]
[ time 434 ] Run JOB 1 at PRIORITY 2 [ TICKS 5 ALLOT 86 TIME 55 (of 200) ]
[ time 435 ] Run JOB 1 at PRIORITY 2 [ TICKS 4 ALLOT 86 TIME 54 (of 200) ]
[ time 436 ] Run JOB 1 at PRIORITY 2 [ TICKS 3 ALLOT 86 TIME 53 (of 200) ]
[ time 437 ] Run JOB 1 at PRIORITY 2 [ TICKS 2 ALLOT 86 TIME 52 (of 200) ]
[ time 438 ] Run JOB 1 at PRIORITY 2 [ TICKS 1 ALLOT 86 TIME 51 (of 200) ]
[ time 439 ] Run JOB 1 at PRIORITY 2 [ TICKS 0 ALLOT 86 TIME 50 (of 200) ]
[ time 440 ] Run JOB 2 at PRIORITY 2 [ TICKS 9 ALLOT 86 TIME 359 (of 500) ]
[ time 441 ] Run JOB 2 at PRIORITY 2 [ TICKS 8 ALLOT 86 TIME 358 (of 500) ]
[ time 442 ] Run JOB 2 at PRIORITY 2 [ TICKS 7 ALLOT 86 TIME 357 (of 500) ]
[ time 443 ] Run JOB 2 at PRIORITY 2 [ TICKS 6 ALLOT 86 TIME 356 (of 500) ]
[ time 444 ] Run JOB 2 at PRIORITY 2 [ TICKS 5 ALLOT 86 TIME 355 (of 500) ]
[ time 445 ] Run JOB 2 at PRIORITY 2 [ TICKS 4 ALLOT 86 TIME 354 (of 500) ]
[ time 446 ] Run JOB 2 at PRIORITY 2 [ TICKS 3 ALLOT 86 TIME 353 (of 500) ]
[ time 447 ] Run JOB 2 at PRIORITY 2 [ TICKS 2 ALLOT 86 TIME 352 (of 500) ]
[ time 448 ] Run JOB 2 at PRIORITY 2 [ TICKS 1 ALLOT 86 TIME 351 (of 500) ]
[ time 449 ] Run JOB 2 at PRIORITY 2 [ TICKS 0 ALLOT 86 TIME 350 (of 500) ]
[ time 450 ] Run JOB 0 at PRIORITY 2 [ TICKS 9 ALLOT 85 TIME 29 (of 180) ]
[ time 451 ] Run JOB 0 at PRIORITY 2 [ TICKS 8 ALLOT 85 TIME 28 (of 180) ]
[ time 452 ] Run JOB 0 at PRIORITY 2 [ TICKS 7 ALLOT 85 TIME 27 (of 180) ]
[ time 453 ] Run JOB 0 at PRIORITY 2 [ TICKS 6 ALLOT 85 TIME 26 (of 180) ]
[ time 454 ] Run JOB 0 at PRIORITY 2 [ TICKS 5 ALLOT 85 TIME 25 (of 180) ]
[ time 455 ] Run JOB 0 at PRIORITY 2 [ TICKS 4 ALLOT 85 TIME 24 (of 180) ]
[ time 456 ] Run JOB 0 at PRIORITY 2 [ TICKS 3 ALLOT 85 TIME 23 (of 180) ]
[ time 457 ] Run JOB 0 at PRIORITY 2 [ TICKS 2 ALLOT 85 TIME 22 (of 180) ]
[ time 458 ] Run JOB 0 at PRIORITY 2 [ TICKS 1 ALLOT 85 TIME 21 (of 180) ]
[ time 459 ] Run JOB 0 at PRIORITY 2 [ TICKS 0 ALLOT 85 TIME 20 (of 180) ]
[ time 460 ] Run JOB 1 at PRIORITY 2 [ TICKS 9 ALLOT 85 TIME 49 (of 200) ]
[ time 461 ] Run JOB 1 at PRIORITY 2 [ TICKS 8 ALLOT 85 TIME 48 (of 200) ]
[ time 462 ] Run JOB 1 at PRIORITY 2 [ TICKS 7 ALLOT 85 TIME 47 (of 200) ]
[ time 463 ] Run JOB 1 at PRIORITY 2 [ TICKS 6 ALLOT 85 TIME 46 (of 200) ]
[ time 464 ] Run JOB 1 at PRIORITY 2 [ TICKS 5 ALLOT 85 TIME 45 (of 200) ]
[ time 465 ] Run JOB 1 at PRIORITY 2 [ TICKS 4 ALLOT 85 TIME 44 (of 200) ]
[ time 466 ] Run JOB 1 at PRIORITY 2 [ TICKS 3 ALLOT 85 TIME 43 (of 200) ]
[ time 467 ] Run JOB 1 at PRIORITY 2 [ TICKS 2 ALLOT 85 TIME 42 (of 200) ]
[ time 468 ] Run JOB 1 at PRIORITY 2 [ TICKS 1 ALLOT 85 TIME 41 (of 200) ]
[ time 469 ] Run JOB 1 at PRIORITY 2 [ TICKS 0 ALLOT 85 TIME 40 (of 200) ]
[ time 470 ] Run JOB 2 at PRIORITY 2 [ TICKS 9 ALLOT 85 TIME 349 (of 500) ]
[ time 471 ] Run JOB 2 at PRIORITY 2 [ TICKS 8 ALLOT 85 TIME 348 (of 500) ]
[ time 472 ] Run JOB 2 at PRIORITY 2 [ TICKS 7 ALLOT 85 TIME 347 (of 500) ]
[ time 473 ] Run JOB 2 at PRIORITY 2 [ TICKS 6 ALLOT 85 TIME 346 (of 500) ]
[ time 474 ] Run JOB 2 at PRIORITY 2 [ TICKS 5 ALLOT 85 TIME 345 (of 500) ]
[ time 475 ] Run JOB 2 at PRIORITY 2 [ TICKS 4 ALLOT 85 TIME 344 (of 500) ]
[ time 476 ] Run JOB 2 at PRIORITY 2 [ TICKS 3 ALLOT 85 TIME 343 (of 500) ]
[ time 477 ] Run JOB 2 at PRIORITY 2 [ TICKS 2 ALLOT 85 TIME 342 (of 500) ]
[ time 478 ] Run JOB 2 at PRIORITY 2 [ TICKS 1 ALLOT 85 TIME 341 (of 500) ]
[ time 479 ] Run JOB 2 at PRIORITY 2 [ TICKS 0 ALLOT 85 TIME 340 (of 500) ]
[ time 480 ] Run JOB 0 at PRIORITY 2 [ TICKS 9 ALLOT 84 TIME 19 (of 180) ]
[ time 481 ] Run JOB 0 at PRIORITY 2 [ TICKS 8 ALLOT 84 TIME 18 (of 180) ]
[ time 482 ] Run JOB 0 at PRIORITY 2 [ TICKS 7 ALLOT 84 TIME 17 (of 180) ]
[ time 483 ] Run JOB 0 at PRIORITY 2 [ TICKS 6 ALLOT 84 TIME 16 (of 180) ]
[ time 484 ] Run JOB 0 at PRIORITY 2 [ TICKS 5 ALLOT 84 TIME 15 (of 180) ]
[ time 485 ] Run JOB 0 at PRIORITY 2 [ TICKS 4 ALLOT 84 TIME 14 (of 180) ]
[ time 486 ] Run JOB 0 at PRIORITY 2 [ TICKS 3 ALLOT 84 TIME 13 (of 180) ]
[ time 487 ] Run JOB 0 at PRIORITY 2 [ TICKS 2 ALLOT 84 TIME 12 (of 180) ]
[ time 488 ] Run JOB 0 at PRIORITY 2 [ TICKS 1 ALLOT 84 TIME 11 (of 180) ]
[ time 489 ] Run JOB 0 at PRIORITY 2 [ TICKS 0 ALLOT 84 TIME 10 (of 180) ]
[ time 490 ] Run JOB 1 at PRIORITY 2 [ TICKS 9 ALLOT 84 TIME 39 (of 200) ]
[ time 491 ] Run JOB 1 at PRIORITY 2 [ TICKS 8 ALLOT 84 TIME 38 (of 200) ]
[ time 492 ] Run JOB 1 at PRIORITY 2 [ TICKS 7 ALLOT 84 TIME 37 (of 200) ]
[ time 493 ] Run JOB 1 at PRIORITY 2 [ TICKS 6 ALLOT 84 TIME 36 (of 200) ]
[ time 494 ] Run JOB 1 at PRIORITY 2 [ TICKS 5 ALLOT 84 TIME 35 (of 200) ]
[ time 495 ] Run JOB 1 at PRIORITY 2 [ TICKS 4 ALLOT 84 TIME 34 (of 200) ]
[ time 496 ] Run JOB 1 at PRIORITY 2 [ TICKS 3 ALLOT 84 TIME 33 (of 200) ]
[ time 497 ] Run JOB 1 at PRIORITY 2 [ TICKS 2 ALLOT 84 TIME 32 (of 200) ]
[ time 498 ] Run JOB 1 at PRIORITY 2 [ TICKS 1 ALLOT 84 TIME 31 (of 200) ]
[ time 499 ] Run JOB 1 at PRIORITY 2 [ TICKS 0 ALLOT 84 TIME 30 (of 200) ]
[ time 500 ] BOOST ( every 500 )
[ time 500 ] Run JOB 2 at PRIORITY 2 [ TICKS 9 ALLOT 100 TIME 339 (of 500) ]
[ time 501 ] Run JOB 2 at PRIORITY 2 [ TICKS 8 ALLOT 100 TIME 338 (of 500) ]
[ time 502 ] Run JOB 2 at PRIORITY 2 [ TICKS 7 ALLOT 100 TIME 337 (of 500) ]
[ time 503 ] Run JOB 2 at PRIORITY 2 [ TICKS 6 ALLOT 100 TIME 336 (of 500) ]
[ time 504 ] Run JOB 2 at PRIORITY 2 [ TICKS 5 ALLOT 100 TIME 335 (of 500) ]
[ time 505 ] Run JOB 2 at PRIORITY 2 [ TICKS 4 ALLOT 100 TIME 334 (of 500) ]
[ time 506 ] Run JOB 2 at PRIORITY 2 [ TICKS 3 ALLOT 100 TIME 333 (of 500) ]
[ time 507 ] Run JOB 2 at PRIORITY 2 [ TICKS 2 ALLOT 100 TIME 332 (of 500) ]
[ time 508 ] Run JOB 2 at PRIORITY 2 [ TICKS 1 ALLOT 100 TIME 331 (of 500) ]
[ time 509 ] Run JOB 2 at PRIORITY 2 [ TICKS 0 ALLOT 100 TIME 330 (of 500) ]
[ time 510 ] Run JOB 0 at PRIORITY 2 [ TICKS 9 ALLOT 100 TIME 9 (of 180) ]
[ time 511 ] Run JOB 0 at PRIORITY 2 [ TICKS 8 ALLOT 100 TIME 8 (of 180) ]
[ time 512 ] Run JOB 0 at PRIORITY 2 [ TICKS 7 ALLOT 100 TIME 7 (of 180) ]
[ time 513 ] Run JOB 0 at PRIORITY 2 [ TICKS 6 ALLOT 100 TIME 6 (of 180) ]
[ time 514 ] Run JOB 0 at PRIORITY 2 [ TICKS 5 ALLOT 100 TIME 5 (of 180) ]
[ time 515 ] Run JOB 0 at PRIORITY 2 [ TICKS 4 ALLOT 100 TIME 4 (of 180) ]
[ time 516 ] Run JOB 0 at PRIORITY 2 [ TICKS 3 ALLOT 100 TIME 3 (of 180) ]
[ time 517 ] Run JOB 0 at PRIORITY 2 [ TICKS 2 ALLOT 100 TIME 2 (of 180) ]
[ time 518 ] Run JOB 0 at PRIORITY 2 [ TICKS 1 ALLOT 100 TIME 1 (of 180) ]
[ time 519 ] Run JOB 0 at PRIORITY 2 [ TICKS 0 ALLOT 100 TIME 0 (of 180) ]
[ time 520 ] FINISHED JOB 0
[ time 520 ] Run JOB 1 at PRIORITY 2 [ TICKS 9 ALLOT 100 TIME 29 (of 200) ]
[ time 521 ] Run JOB 1 at PRIORITY 2 [ TICKS 8 ALLOT 100 TIME 28 (of 200) ]
[ time 522 ] Run JOB 1 at PRIORITY 2 [ TICKS 7 ALLOT 100 TIME 27 (of 200) ]
[ time 523 ] Run JOB 1 at PRIORITY 2 [ TICKS 6 ALLOT 100 TIME 26 (of 200) ]
[ time 524 ] Run JOB 1 at PRIORITY 2 [ TICKS 5 ALLOT 100 TIME 25 (of 200) ]
[ time 525 ] Run JOB 1 at PRIORITY 2 [ TICKS 4 ALLOT 100 TIME 24 (of 200) ]
[ time 526 ] Run JOB 1 at PRIORITY 2 [ TICKS 3 ALLOT 100 TIME 23 (of 200) ]
[ time 527 ] Run JOB 1 at PRIORITY 2 [ TICKS 2 ALLOT 100 TIME 22 (of 200) ]
[ time 528 ] Run JOB 1 at PRIORITY 2 [ TICKS 1 ALLOT 100 TIME 21 (of 200) ]
[ time 529 ] Run JOB 1 at PRIORITY 2 [ TICKS 0 ALLOT 100 TIME 20 (of 200) ]
[ time 530 ] Run JOB 2 at PRIORITY 2 [ TICKS 9 ALLOT 99 TIME 329 (of 500) ]
[ time 531 ] Run JOB 2 at PRIORITY 2 [ TICKS 8 ALLOT 99 TIME 328 (of 500) ]
[ time 532 ] Run JOB 2 at PRIORITY 2 [ TICKS 7 ALLOT 99 TIME 327 (of 500) ]
[ time 533 ] Run JOB 2 at PRIORITY 2 [ TICKS 6 ALLOT 99 TIME 326 (of 500) ]
[ time 534 ] Run JOB 2 at PRIORITY 2 [ TICKS 5 ALLOT 99 TIME 325 (of 500) ]
[ time 535 ] Run JOB 2 at PRIORITY 2 [ TICKS 4 ALLOT 99 TIME 324 (of 500) ]
[ time 536 ] Run JOB 2 at PRIORITY 2 [ TICKS 3 ALLOT 99 TIME 323 (of 500) ]
[ time 537 ] Run JOB 2 at PRIORITY 2 [ TICKS 2 ALLOT 99 TIME 322 (of 500) ]
[ time 538 ] Run JOB 2 at PRIORITY 2 [ TICKS 1 ALLOT 99 TIME 321 (of 500) ]
[ time 539 ] Run JOB 2 at PRIORITY 2 [ TICKS 0 ALLOT 99 TIME 320 (of 500) ]
[ time 540 ] Run JOB 1 at PRIORITY 2 [ TICKS 9 ALLOT 99 TIME 19 (of 200) ]
[ time 541 ] Run JOB 1 at PRIORITY 2 [ TICKS 8 ALLOT 99 TIME 18 (of 200) ]
[ time 542 ] Run JOB 1 at PRIORITY 2 [ TICKS 7 ALLOT 99 TIME 17 (of 200) ]
[ time 543 ] Run JOB 1 at PRIORITY 2 [ TICKS 6 ALLOT 99 TIME 16 (of 200) ]
[ time 544 ] Run JOB 1 at PRIORITY 2 [ TICKS 5 ALLOT 99 TIME 15 (of 200) ]
[ time 545 ] Run JOB 1 at PRIORITY 2 [ TICKS 4 ALLOT 99 TIME 14 (of 200) ]
[ time 546 ] Run JOB 1 at PRIORITY 2 [ TICKS 3 ALLOT 99 TIME 13 (of 200) ]
[ time 547 ] Run JOB 1 at PRIORITY 2 [ TICKS 2 ALLOT 99 TIME 12 (of 200) ]
[ time 548 ] Run JOB 1 at PRIORITY 2 [ TICKS 1 ALLOT 99 TIME 11 (of 200) ]
[ time 549 ] Run JOB 1 at PRIORITY 2 [ TICKS 0 ALLOT 99 TIME 10 (of 200) ]
[ time 550 ] Run JOB 2 at PRIORITY 2 [ TICKS 9 ALLOT 98 TIME 319 (of 500) ]
[ time 551 ] Run JOB 2 at PRIORITY 2 [ TICKS 8 ALLOT 98 TIME 318 (of 500) ]
[ time 552 ] Run JOB 2 at PRIORITY 2 [ TICKS 7 ALLOT 98 TIME 317 (of 500) ]
[ time 553 ] Run JOB 2 at PRIORITY 2 [ TICKS 6 ALLOT 98 TIME 316 (of 500) ]
[ time 554 ] Run JOB 2 at PRIORITY 2 [ TICKS 5 ALLOT 98 TIME 315 (of 500) ]
[ time 555 ] Run JOB 2 at PRIORITY 2 [ TICKS 4 ALLOT 98 TIME 314 (of 500) ]
[ time 556 ] Run JOB 2 at PRIORITY 2 [ TICKS 3 ALLOT 98 TIME 313 (of 500) ]
[ time 557 ] Run JOB 2 at PRIORITY 2 [ TICKS 2 ALLOT 98 TIME 312 (of 500) ]
[ time 558 ] Run JOB 2 at PRIORITY 2 [ TICKS 1 ALLOT 98 TIME 311 (of 500) ]
[ time 559 ] Run JOB 2 at PRIORITY 2 [ TICKS 0 ALLOT 98 TIME 310 (of 500) ]
[ time 560 ] Run JOB 1 at PRIORITY 2 [ TICKS 9 ALLOT 98 TIME 9 (of 200) ]
[ time 561 ] Run JOB 1 at PRIORITY 2 [ TICKS 8 ALLOT 98 TIME 8 (of 200) ]
[ time 562 ] Run JOB 1 at PRIORITY 2 [ TICKS 7 ALLOT 98 TIME 7 (of 200) ]
[ time 563 ] Run JOB 1 at PRIORITY 2 [ TICKS 6 ALLOT 98 TIME 6 (of 200) ]
[ time 564 ] Run JOB 1 at PRIORITY 2 [ TICKS 5 ALLOT 98 TIME 5 (of 200) ]
[ time 565 ] Run JOB 1 at PRIORITY 2 [ TICKS 4 ALLOT 98 TIME 4 (of 200) ]
[ time 566 ] Run JOB 1 at PRIORITY 2 [ TICKS 3 ALLOT 98 TIME 3 (of 200) ]
[ time 567 ] Run JOB 1 at PRIORITY 2 [ TICKS 2 ALLOT 98 TIME 2 (of 200) ]
[ time 568 ] Run JOB 1 at PRIORITY 2 [ TICKS 1 ALLOT 98 TIME 1 (of 200) ]
[ time 569 ] Run JOB 1 at PRIORITY 2 [ TICKS 0 ALLOT 98 TIME 0 (of 200) ]
[ time 570 ] FINISHED JOB 1
[ time 570 ] Run JOB 2 at PRIORITY 2 [ TICKS 9 ALLOT 97 TIME 309 (of 500) ]
[ time 571 ] Run JOB 2 at PRIORITY 2 [ TICKS 8 ALLOT 97 TIME 308 (of 500) ]
[ time 572 ] Run JOB 2 at PRIORITY 2 [ TICKS 7 ALLOT 97 TIME 307 (of 500) ]
[ time 573 ] Run JOB 2 at PRIORITY 2 [ TICKS 6 ALLOT 97 TIME 306 (of 500) ]
[ time 574 ] Run JOB 2 at PRIORITY 2 [ TICKS 5 ALLOT 97 TIME 305 (of 500) ]
[ time 575 ] Run JOB 2 at PRIORITY 2 [ TICKS 4 ALLOT 97 TIME 304 (of 500) ]
[ time 576 ] Run JOB 2 at PRIORITY 2 [ TICKS 3 ALLOT 97 TIME 303 (of 500) ]
[ time 577 ] Run JOB 2 at PRIORITY 2 [ TICKS 2 ALLOT 97 TIME 302 (of 500) ]
[ time 578 ] Run JOB 2 at PRIORITY 2 [ TICKS 1 ALLOT 97 TIME 301 (of 500) ]
[ time 579 ] Run JOB 2 at PRIORITY 2 [ TICKS 0 ALLOT 97 TIME 300 (of 500) ]
[ time 580 ] Run JOB 2 at PRIORITY 2 [ TICKS 9 ALLOT 96 TIME 299 (of 500) ]
[ time 581 ] Run JOB 2 at PRIORITY 2 [ TICKS 8 ALLOT 96 TIME 298 (of 500) ]
[ time 582 ] Run JOB 2 at PRIORITY 2 [ TICKS 7 ALLOT 96 TIME 297 (of 500) ]
[ time 583 ] Run JOB 2 at PRIORITY 2 [ TICKS 6 ALLOT 96 TIME 296 (of 500) ]
[ time 584 ] Run JOB 2 at PRIORITY 2 [ TICKS 5 ALLOT 96 TIME 295 (of 500) ]
[ time 585 ] Run JOB 2 at PRIORITY 2 [ TICKS 4 ALLOT 96 TIME 294 (of 500) ]
[ time 586 ] Run JOB 2 at PRIORITY 2 [ TICKS 3 ALLOT 96 TIME 293 (of 500) ]
[ time 587 ] Run JOB 2 at PRIORITY 2 [ TICKS 2 ALLOT 96 TIME 292 (of 500) ]
[ time 588 ] Run JOB 2 at PRIORITY 2 [ TICKS 1 ALLOT 96 TIME 291 (of 500) ]
[ time 589 ] Run JOB 2 at PRIORITY 2 [ TICKS 0 ALLOT 96 TIME 290 (of 500) ]
[ time 590 ] Run JOB 2 at PRIORITY 2 [ TICKS 9 ALLOT 95 TIME 289 (of 500) ]
[ time 591 ] Run JOB 2 at PRIORITY 2 [ TICKS 8 ALLOT 95 TIME 288 (of 500) ]
[ time 592 ] Run JOB 2 at PRIORITY 2 [ TICKS 7 ALLOT 95 TIME 287 (of 500) ]
[ time 593 ] Run JOB 2 at PRIORITY 2 [ TICKS 6 ALLOT 95 TIME 286 (of 500) ]
[ time 594 ] Run JOB 2 at PRIORITY 2 [ TICKS 5 ALLOT 95 TIME 285 (of 500) ]
[ time 595 ] Run JOB 2 at PRIORITY 2 [ TICKS 4 ALLOT 95 TIME 284 (of 500) ]
[ time 596 ] Run JOB 2 at PRIORITY 2 [ TICKS 3 ALLOT 95 TIME 283 (of 500) ]
[ time 597 ] Run JOB 2 at PRIORITY 2 [ TICKS 2 ALLOT 95 TIME 282 (of 500) ]
[ time 598 ] Run JOB 2 at PRIORITY 2 [ TICKS 1 ALLOT 95 TIME 281 (of 500) ]
[ time 599 ] Run JOB 2 at PRIORITY 2 [ TICKS 0 ALLOT 95 TIME 280 (of 500) ]
[ time 600 ] Run JOB 2 at PRIORITY 2 [ TICKS 9 ALLOT 94 TIME 279 (of 500) ]
[ time 601 ] Run JOB 2 at PRIORITY 2 [ TICKS 8 ALLOT 94 TIME 278 (of 500) ]
[ time 602 ] Run JOB 2 at PRIORITY 2 [ TICKS 7 ALLOT 94 TIME 277 (of 500) ]
[ time 603 ] Run JOB 2 at PRIORITY 2 [ TICKS 6 ALLOT 94 TIME 276 (of 500) ]
[ time 604 ] Run JOB 2 at PRIORITY 2 [ TICKS 5 ALLOT 94 TIME 275 (of 500) ]
[ time 605 ] Run JOB 2 at PRIORITY 2 [ TICKS 4 ALLOT 94 TIME 274 (of 500) ]
[ time 606 ] Run JOB 2 at PRIORITY 2 [ TICKS 3 ALLOT 94 TIME 273 (of 500) ]
[ time 607 ] Run JOB 2 at PRIORITY 2 [ TICKS 2 ALLOT 94 TIME 272 (of 500) ]
[ time 608 ] Run JOB 2 at PRIORITY 2 [ TICKS 1 ALLOT 94 TIME 271 (of 500) ]
[ time 609 ] Run JOB 2 at PRIORITY 2 [ TICKS 0 ALLOT 94 TIME 270 (of 500) ]
[ time 610 ] Run JOB 2 at PRIORITY 2 [ TICKS 9 ALLOT 93 TIME 269 (of 500) ]
[ time 611 ] Run JOB 2 at PRIORITY 2 [ TICKS 8 ALLOT 93 TIME 268 (of 500) ]
[ time 612 ] Run JOB 2 at PRIORITY 2 [ TICKS 7 ALLOT 93 TIME 267 (of 500) ]
[ time 613 ] Run JOB 2 at PRIORITY 2 [ TICKS 6 ALLOT 93 TIME 266 (of 500) ]
[ time 614 ] Run JOB 2 at PRIORITY 2 [ TICKS 5 ALLOT 93 TIME 265 (of 500) ]
[ time 615 ] Run JOB 2 at PRIORITY 2 [ TICKS 4 ALLOT 93 TIME 264 (of 500) ]
[ time 616 ] Run JOB 2 at PRIORITY 2 [ TICKS 3 ALLOT 93 TIME 263 (of 500) ]
[ time 617 ] Run JOB 2 at PRIORITY 2 [ TICKS 2 ALLOT 93 TIME 262 (of 500) ]
[ time 618 ] Run JOB 2 at PRIORITY 2 [ TICKS 1 ALLOT 93 TIME 261 (of 500) ]
[ time 619 ] Run JOB 2 at PRIORITY 2 [ TICKS 0 ALLOT 93 TIME 260 (of 500) ]
[ time 620 ] Run JOB 2 at PRIORITY 2 [ TICKS 9 ALLOT 92 TIME 259 (of 500) ]
[ time 621 ] Run JOB 2 at PRIORITY 2 [ TICKS 8 ALLOT 92 TIME 258 (of 500) ]
[ time 622 ] Run JOB 2 at PRIORITY 2 [ TICKS 7 ALLOT 92 TIME 257 (of 500) ]
[ time 623 ] Run JOB 2 at PRIORITY 2 [ TICKS 6 ALLOT 92 TIME 256 (of 500) ]
[ time 624 ] Run JOB 2 at PRIORITY 2 [ TICKS 5 ALLOT 92 TIME 255 (of 500) ]
[ time 625 ] Run JOB 2 at PRIORITY 2 [ TICKS 4 ALLOT 92 TIME 254 (of 500) ]
[ time 626 ] Run JOB 2 at PRIORITY 2 [ TICKS 3 ALLOT 92 TIME 253 (of 500) ]
[ time 627 ] Run JOB 2 at PRIORITY 2 [ TICKS 2 ALLOT 92 TIME 252 (of 500) ]
[ time 628 ] Run JOB 2 at PRIORITY 2 [ TICKS 1 ALLOT 92 TIME 251 (of 500) ]
[ time 629 ] Run JOB 2 at PRIORITY 2 [ TICKS 0 ALLOT 92 TIME 250 (of 500) ]
[ time 630 ] Run JOB 2 at PRIORITY 2 [ TICKS 9 ALLOT 91 TIME 249 (of 500) ]
[ time 631 ] Run JOB 2 at PRIORITY 2 [ TICKS 8 ALLOT 91 TIME 248 (of 500) ]
[ time 632 ] Run JOB 2 at PRIORITY 2 [ TICKS 7 ALLOT 91 TIME 247 (of 500) ]
[ time 633 ] Run JOB 2 at PRIORITY 2 [ TICKS 6 ALLOT 91 TIME 246 (of 500) ]
[ time 634 ] Run JOB 2 at PRIORITY 2 [ TICKS 5 ALLOT 91 TIME 245 (of 500) ]
[ time 635 ] Run JOB 2 at PRIORITY 2 [ TICKS 4 ALLOT 91 TIME 244 (of 500) ]
[ time 636 ] Run JOB 2 at PRIORITY 2 [ TICKS 3 ALLOT 91 TIME 243 (of 500) ]
[ time 637 ] Run JOB 2 at PRIORITY 2 [ TICKS 2 ALLOT 91 TIME 242 (of 500) ]
[ time 638 ] Run JOB 2 at PRIORITY 2 [ TICKS 1 ALLOT 91 TIME 241 (of 500) ]
[ time 639 ] Run JOB 2 at PRIORITY 2 [ TICKS 0 ALLOT 91 TIME 240 (of 500) ]
[ time 640 ] Run JOB 2 at PRIORITY 2 [ TICKS 9 ALLOT 90 TIME 239 (of 500) ]
[ time 641 ] Run JOB 2 at PRIORITY 2 [ TICKS 8 ALLOT 90 TIME 238 (of 500) ]
[ time 642 ] Run JOB 2 at PRIORITY 2 [ TICKS 7 ALLOT 90 TIME 237 (of 500) ]
[ time 643 ] Run JOB 2 at PRIORITY 2 [ TICKS 6 ALLOT 90 TIME 236 (of 500) ]
[ time 644 ] Run JOB 2 at PRIORITY 2 [ TICKS 5 ALLOT 90 TIME 235 (of 500) ]
[ time 645 ] Run JOB 2 at PRIORITY 2 [ TICKS 4 ALLOT 90 TIME 234 (of 500) ]
[ time 646 ] Run JOB 2 at PRIORITY 2 [ TICKS 3 ALLOT 90 TIME 233 (of 500) ]
[ time 647 ] Run JOB 2 at PRIORITY 2 [ TICKS 2 ALLOT 90 TIME 232 (of 500) ]
[ time 648 ] Run JOB 2 at PRIORITY 2 [ TICKS 1 ALLOT 90 TIME 231 (of 500) ]
[ time 649 ] Run JOB 2 at PRIORITY 2 [ TICKS 0 ALLOT 90 TIME 230 (of 500) ]
[ time 650 ] Run JOB 2 at PRIORITY 2 [ TICKS 9 ALLOT 89 TIME 229 (of 500) ]
[ time 651 ] Run JOB 2 at PRIORITY 2 [ TICKS 8 ALLOT 89 TIME 228 (of 500) ]
[ time 652 ] Run JOB 2 at PRIORITY 2 [ TICKS 7 ALLOT 89 TIME 227 (of 500) ]
[ time 653 ] Run JOB 2 at PRIORITY 2 [ TICKS 6 ALLOT 89 TIME 226 (of 500) ]
[ time 654 ] Run JOB 2 at PRIORITY 2 [ TICKS 5 ALLOT 89 TIME 225 (of 500) ]
[ time 655 ] Run JOB 2 at PRIORITY 2 [ TICKS 4 ALLOT 89 TIME 224 (of 500) ]
[ time 656 ] Run JOB 2 at PRIORITY 2 [ TICKS 3 ALLOT 89 TIME 223 (of 500) ]
[ time 657 ] Run JOB 2 at PRIORITY 2 [ TICKS 2 ALLOT 89 TIME 222 (of 500) ]
[ time 658 ] Run JOB 2 at PRIORITY 2 [ TICKS 1 ALLOT 89 TIME 221 (of 500) ]
[ time 659 ] Run JOB 2 at PRIORITY 2 [ TICKS 0 ALLOT 89 TIME 220 (of 500) ]
[ time 660 ] Run JOB 2 at PRIORITY 2 [ TICKS 9 ALLOT 88 TIME 219 (of 500) ]
[ time 661 ] Run JOB 2 at PRIORITY 2 [ TICKS 8 ALLOT 88 TIME 218 (of 500) ]
[ time 662 ] Run JOB 2 at PRIORITY 2 [ TICKS 7 ALLOT 88 TIME 217 (of 500) ]
[ time 663 ] Run JOB 2 at PRIORITY 2 [ TICKS 6 ALLOT 88 TIME 216 (of 500) ]
[ time 664 ] Run JOB 2 at PRIORITY 2 [ TICKS 5 ALLOT 88 TIME 215 (of 500) ]
[ time 665 ] Run JOB 2 at PRIORITY 2 [ TICKS 4 ALLOT 88 TIME 214 (of 500) ]
[ time 666 ] Run JOB 2 at PRIORITY 2 [ TICKS 3 ALLOT 88 TIME 213 (of 500) ]
[ time 667 ] Run JOB 2 at PRIORITY 2 [ TICKS 2 ALLOT 88 TIME 212 (of 500) ]
[ time 668 ] Run JOB 2 at PRIORITY 2 [ TICKS 1 ALLOT 88 TIME 211 (of 500) ]
[ time 669 ] Run JOB 2 at PRIORITY 2 [ TICKS 0 ALLOT 88 TIME 210 (of 500) ]
[ time 670 ] Run JOB 2 at PRIORITY 2 [ TICKS 9 ALLOT 87 TIME 209 (of 500) ]
[ time 671 ] Run JOB 2 at PRIORITY 2 [ TICKS 8 ALLOT 87 TIME 208 (of 500) ]
[ time 672 ] Run JOB 2 at PRIORITY 2 [ TICKS 7 ALLOT 87 TIME 207 (of 500) ]
[ time 673 ] Run JOB 2 at PRIORITY 2 [ TICKS 6 ALLOT 87 TIME 206 (of 500) ]
[ time 674 ] Run JOB 2 at PRIORITY 2 [ TICKS 5 ALLOT 87 TIME 205 (of 500) ]
[ time 675 ] Run JOB 2 at PRIORITY 2 [ TICKS 4 ALLOT 87 TIME 204 (of 500) ]
[ time 676 ] Run JOB 2 at PRIORITY 2 [ TICKS 3 ALLOT 87 TIME 203 (of 500) ]
[ time 677 ] Run JOB 2 at PRIORITY 2 [ TICKS 2 ALLOT 87 TIME 202 (of 500) ]
[ time 678 ] Run JOB 2 at PRIORITY 2 [ TICKS 1 ALLOT 87 TIME 201 (of 500) ]
[ time 679 ] Run JOB 2 at PRIORITY 2 [ TICKS 0 ALLOT 87 TIME 200 (of 500) ]
[ time 680 ] Run JOB 2 at PRIORITY 2 [ TICKS 9 ALLOT 86 TIME 199 (of 500) ]
[ time 681 ] Run JOB 2 at PRIORITY 2 [ TICKS 8 ALLOT 86 TIME 198 (of 500) ]
[ time 682 ] Run JOB 2 at PRIORITY 2 [ TICKS 7 ALLOT 86 TIME 197 (of 500) ]
[ time 683 ] Run JOB 2 at PRIORITY 2 [ TICKS 6 ALLOT 86 TIME 196 (of 500) ]
[ time 684 ] Run JOB 2 at PRIORITY 2 [ TICKS 5 ALLOT 86 TIME 195 (of 500) ]
[ time 685 ] Run JOB 2 at PRIORITY 2 [ TICKS 4 ALLOT 86 TIME 194 (of 500) ]
[ time 686 ] Run JOB 2 at PRIORITY 2 [ TICKS 3 ALLOT 86 TIME 193 (of 500) ]
[ time 687 ] Run JOB 2 at PRIORITY 2 [ TICKS 2 ALLOT 86 TIME 192 (of 500) ]
[ time 688 ] Run JOB 2 at PRIORITY 2 [ TICKS 1 ALLOT 86 TIME 191 (of 500) ]
[ time 689 ] Run JOB 2 at PRIORITY 2 [ TICKS 0 ALLOT 86 TIME 190 (of 500) ]
[ time 690 ] Run JOB 2 at PRIORITY 2 [ TICKS 9 ALLOT 85 TIME 189 (of 500) ]
[ time 691 ] Run JOB 2 at PRIORITY 2 [ TICKS 8 ALLOT 85 TIME 188 (of 500) ]
[ time 692 ] Run JOB 2 at PRIORITY 2 [ TICKS 7 ALLOT 85 TIME 187 (of 500) ]
[ time 693 ] Run JOB 2 at PRIORITY 2 [ TICKS 6 ALLOT 85 TIME 186 (of 500) ]
[ time 694 ] Run JOB 2 at PRIORITY 2 [ TICKS 5 ALLOT 85 TIME 185 (of 500) ]
[ time 695 ] Run JOB 2 at PRIORITY 2 [ TICKS 4 ALLOT 85 TIME 184 (of 500) ]
[ time 696 ] Run JOB 2 at PRIORITY 2 [ TICKS 3 ALLOT 85 TIME 183 (of 500) ]
[ time 697 ] Run JOB 2 at PRIORITY 2 [ TICKS 2 ALLOT 85 TIME 182 (of 500) ]
[ time 698 ] Run JOB 2 at PRIORITY 2 [ TICKS 1 ALLOT 85 TIME 181 (of 500) ]
[ time 699 ] Run JOB 2 at PRIORITY 2 [ TICKS 0 ALLOT 85 TIME 180 (of 500) ]
[ time 700 ] Run JOB 2 at PRIORITY 2 [ TICKS 9 ALLOT 84 TIME 179 (of 500) ]
[ time 701 ] Run JOB 2 at PRIORITY 2 [ TICKS 8 ALLOT 84 TIME 178 (of 500) ]
[ time 702 ] Run JOB 2 at PRIORITY 2 [ TICKS 7 ALLOT 84 TIME 177 (of 500) ]
[ time 703 ] Run JOB 2 at PRIORITY 2 [ TICKS 6 ALLOT 84 TIME 176 (of 500) ]
[ time 704 ] Run JOB 2 at PRIORITY 2 [ TICKS 5 ALLOT 84 TIME 175 (of 500) ]
[ time 705 ] Run JOB 2 at PRIORITY 2 [ TICKS 4 ALLOT 84 TIME 174 (of 500) ]
[ time 706 ] Run JOB 2 at PRIORITY 2 [ TICKS 3 ALLOT 84 TIME 173 (of 500) ]
[ time 707 ] Run JOB 2 at PRIORITY 2 [ TICKS 2 ALLOT 84 TIME 172 (of 500) ]
[ time 708 ] Run JOB 2 at PRIORITY 2 [ TICKS 1 ALLOT 84 TIME 171 (of 500) ]
[ time 709 ] Run JOB 2 at PRIORITY 2 [ TICKS 0 ALLOT 84 TIME 170 (of 500) ]
[ time 710 ] Run JOB 2 at PRIORITY 2 [ TICKS 9 ALLOT 83 TIME 169 (of 500) ]
[ time 711 ] Run JOB 2 at PRIORITY 2 [ TICKS 8 ALLOT 83 TIME 168 (of 500) ]
[ time 712 ] Run JOB 2 at PRIORITY 2 [ TICKS 7 ALLOT 83 TIME 167 (of 500) ]
[ time 713 ] Run JOB 2 at PRIORITY 2 [ TICKS 6 ALLOT 83 TIME 166 (of 500) ]
[ time 714 ] Run JOB 2 at PRIORITY 2 [ TICKS 5 ALLOT 83 TIME 165 (of 500) ]
[ time 715 ] Run JOB 2 at PRIORITY 2 [ TICKS 4 ALLOT 83 TIME 164 (of 500) ]
[ time 716 ] Run JOB 2 at PRIORITY 2 [ TICKS 3 ALLOT 83 TIME 163 (of 500) ]
[ time 717 ] Run JOB 2 at PRIORITY 2 [ TICKS 2 ALLOT 83 TIME 162 (of 500) ]
[ time 718 ] Run JOB 2 at PRIORITY 2 [ TICKS 1 ALLOT 83 TIME 161 (of 500) ]
[ time 719 ] Run JOB 2 at PRIORITY 2 [ TICKS 0 ALLOT 83 TIME 160 (of 500) ]
[ time 720 ] Run JOB 2 at PRIORITY 2 [ TICKS 9 ALLOT 82 TIME 159 (of 500) ]
[ time 721 ] Run JOB 2 at PRIORITY 2 [ TICKS 8 ALLOT 82 TIME 158 (of 500) ]
[ time 722 ] Run JOB 2 at PRIORITY 2 [ TICKS 7 ALLOT 82 TIME 157 (of 500) ]
[ time 723 ] Run JOB 2 at PRIORITY 2 [ TICKS 6 ALLOT 82 TIME 156 (of 500) ]
[ time 724 ] Run JOB 2 at PRIORITY 2 [ TICKS 5 ALLOT 82 TIME 155 (of 500) ]
[ time 725 ] Run JOB 2 at PRIORITY 2 [ TICKS 4 ALLOT 82 TIME 154 (of 500) ]
[ time 726 ] Run JOB 2 at PRIORITY 2 [ TICKS 3 ALLOT 82 TIME 153 (of 500) ]
[ time 727 ] Run JOB 2 at PRIORITY 2 [ TICKS 2 ALLOT 82 TIME 152 (of 500) ]
[ time 728 ] Run JOB 2 at PRIORITY 2 [ TICKS 1 ALLOT 82 TIME 151 (of 500) ]
[ time 729 ] Run JOB 2 at PRIORITY 2 [ TICKS 0 ALLOT 82 TIME 150 (of 500) ]
[ time 730 ] Run JOB 2 at PRIORITY 2 [ TICKS 9 ALLOT 81 TIME 149 (of 500) ]
[ time 731 ] Run JOB 2 at PRIORITY 2 [ TICKS 8 ALLOT 81 TIME 148 (of 500) ]
[ time 732 ] Run JOB 2 at PRIORITY 2 [ TICKS 7 ALLOT 81 TIME 147 (of 500) ]
[ time 733 ] Run JOB 2 at PRIORITY 2 [ TICKS 6 ALLOT 81 TIME 146 (of 500) ]
[ time 734 ] Run JOB 2 at PRIORITY 2 [ TICKS 5 ALLOT 81 TIME 145 (of 500) ]
[ time 735 ] Run JOB 2 at PRIORITY 2 [ TICKS 4 ALLOT 81 TIME 144 (of 500) ]
[ time 736 ] Run JOB 2 at PRIORITY 2 [ TICKS 3 ALLOT 81 TIME 143 (of 500) ]
[ time 737 ] Run JOB 2 at PRIORITY 2 [ TICKS 2 ALLOT 81 TIME 142 (of 500) ]
[ time 738 ] Run JOB 2 at PRIORITY 2 [ TICKS 1 ALLOT 81 TIME 141 (of 500) ]
[ time 739 ] Run JOB 2 at PRIORITY 2 [ TICKS 0 ALLOT 81 TIME 140 (of 500) ]
[ time 740 ] Run JOB 2 at PRIORITY 2 [ TICKS 9 ALLOT 80 TIME 139 (of 500) ]
[ time 741 ] Run JOB 2 at PRIORITY 2 [ TICKS 8 ALLOT 80 TIME 138 (of 500) ]
[ time 742 ] Run JOB 2 at PRIORITY 2 [ TICKS 7 ALLOT 80 TIME 137 (of 500) ]
[ time 743 ] Run JOB 2 at PRIORITY 2 [ TICKS 6 ALLOT 80 TIME 136 (of 500) ]
[ time 744 ] Run JOB 2 at PRIORITY 2 [ TICKS 5 ALLOT 80 TIME 135 (of 500) ]
[ time 745 ] Run JOB 2 at PRIORITY 2 [ TICKS 4 ALLOT 80 TIME 134 (of 500) ]
[ time 746 ] Run JOB 2 at PRIORITY 2 [ TICKS 3 ALLOT 80 TIME 133 (of 500) ]
[ time 747 ] Run JOB 2 at PRIORITY 2 [ TICKS 2 ALLOT 80 TIME 132 (of 500) ]
[ time 748 ] Run JOB 2 at PRIORITY 2 [ TICKS 1 ALLOT 80 TIME 131 (of 500) ]
[ time 749 ] Run JOB 2 at PRIORITY 2 [ TICKS 0 ALLOT 80 TIME 130 (of 500) ]
[ time 750 ] Run JOB 2 at PRIORITY 2 [ TICKS 9 ALLOT 79 TIME 129 (of 500) ]
[ time 751 ] Run JOB 2 at PRIORITY 2 [ TICKS 8 ALLOT 79 TIME 128 (of 500) ]
[ time 752 ] Run JOB 2 at PRIORITY 2 [ TICKS 7 ALLOT 79 TIME 127 (of 500) ]
[ time 753 ] Run JOB 2 at PRIORITY 2 [ TICKS 6 ALLOT 79 TIME 126 (of 500) ]
[ time 754 ] Run JOB 2 at PRIORITY 2 [ TICKS 5 ALLOT 79 TIME 125 (of 500) ]
[ time 755 ] Run JOB 2 at PRIORITY 2 [ TICKS 4 ALLOT 79 TIME 124 (of 500) ]
[ time 756 ] Run JOB 2 at PRIORITY 2 [ TICKS 3 ALLOT 79 TIME 123 (of 500) ]
[ time 757 ] Run JOB 2 at PRIORITY 2 [ TICKS 2 ALLOT 79 TIME 122 (of 500) ]
[ time 758 ] Run JOB 2 at PRIORITY 2 [ TICKS 1 ALLOT 79 TIME 121 (of 500) ]
[ time 759 ] Run JOB 2 at PRIORITY 2 [ TICKS 0 ALLOT 79 TIME 120 (of 500) ]
[ time 760 ] Run JOB 2 at PRIORITY 2 [ TICKS 9 ALLOT 78 TIME 119 (of 500) ]
[ time 761 ] Run JOB 2 at PRIORITY 2 [ TICKS 8 ALLOT 78 TIME 118 (of 500) ]
[ time 762 ] Run JOB 2 at PRIORITY 2 [ TICKS 7 ALLOT 78 TIME 117 (of 500) ]
[ time 763 ] Run JOB 2 at PRIORITY 2 [ TICKS 6 ALLOT 78 TIME 116 (of 500) ]
[ time 764 ] Run JOB 2 at PRIORITY 2 [ TICKS 5 ALLOT 78 TIME 115 (of 500) ]
[ time 765 ] Run JOB 2 at PRIORITY 2 [ TICKS 4 ALLOT 78 TIME 114 (of 500) ]
[ time 766 ] Run JOB 2 at PRIORITY 2 [ TICKS 3 ALLOT 78 TIME 113 (of 500) ]
[ time 767 ] Run JOB 2 at PRIORITY 2 [ TICKS 2 ALLOT 78 TIME 112 (of 500) ]
[ time 768 ] Run JOB 2 at PRIORITY 2 [ TICKS 1 ALLOT 78 TIME 111 (of 500) ]
[ time 769 ] Run JOB 2 at PRIORITY 2 [ TICKS 0 ALLOT 78 TIME 110 (of 500) ]
[ time 770 ] Run JOB 2 at PRIORITY 2 [ TICKS 9 ALLOT 77 TIME 109 (of 500) ]
[ time 771 ] Run JOB 2 at PRIORITY 2 [ TICKS 8 ALLOT 77 TIME 108 (of 500) ]
[ time 772 ] Run JOB 2 at PRIORITY 2 [ TICKS 7 ALLOT 77 TIME 107 (of 500) ]
[ time 773 ] Run JOB 2 at PRIORITY 2 [ TICKS 6 ALLOT 77 TIME 106 (of 500) ]
[ time 774 ] Run JOB 2 at PRIORITY 2 [ TICKS 5 ALLOT 77 TIME 105 (of 500) ]
[ time 775 ] Run JOB 2 at PRIORITY 2 [ TICKS 4 ALLOT 77 TIME 104 (of 500) ]
[ time 776 ] Run JOB 2 at PRIORITY 2 [ TICKS 3 ALLOT 77 TIME 103 (of 500) ]
[ time 777 ] Run JOB 2 at PRIORITY 2 [ TICKS 2 ALLOT 77 TIME 102 (of 500) ]
[ time 778 ] Run JOB 2 at PRIORITY 2 [ TICKS 1 ALLOT 77 TIME 101 (of 500) ]
[ time 779 ] Run JOB 2 at PRIORITY 2 [ TICKS 0 ALLOT 77 TIME 100 (of 500) ]
[ time 780 ] Run JOB 2 at PRIORITY 2 [ TICKS 9 ALLOT 76 TIME 99 (of 500) ]
[ time 781 ] Run JOB 2 at PRIORITY 2 [ TICKS 8 ALLOT 76 TIME 98 (of 500) ]
[ time 782 ] Run JOB 2 at PRIORITY 2 [ TICKS 7 ALLOT 76 TIME 97 (of 500) ]
[ time 783 ] Run JOB 2 at PRIORITY 2 [ TICKS 6 ALLOT 76 TIME 96 (of 500) ]
[ time 784 ] Run JOB 2 at PRIORITY 2 [ TICKS 5 ALLOT 76 TIME 95 (of 500) ]
[ time 785 ] Run JOB 2 at PRIORITY 2 [ TICKS 4 ALLOT 76 TIME 94 (of 500) ]
[ time 786 ] Run JOB 2 at PRIORITY 2 [ TICKS 3 ALLOT 76 TIME 93 (of 500) ]
[ time 787 ] Run JOB 2 at PRIORITY 2 [ TICKS 2 ALLOT 76 TIME 92 (of 500) ]
[ time 788 ] Run JOB 2 at PRIORITY 2 [ TICKS 1 ALLOT 76 TIME 91 (of 500) ]
[ time 789 ] Run JOB 2 at PRIORITY 2 [ TICKS 0 ALLOT 76 TIME 90 (of 500) ]
[ time 790 ] Run JOB 2 at PRIORITY 2 [ TICKS 9 ALLOT 75 TIME 89 (of 500) ]
[ time 791 ] Run JOB 2 at PRIORITY 2 [ TICKS 8 ALLOT 75 TIME 88 (of 500) ]
[ time 792 ] Run JOB 2 at PRIORITY 2 [ TICKS 7 ALLOT 75 TIME 87 (of 500) ]
[ time 793 ] Run JOB 2 at PRIORITY 2 [ TICKS 6 ALLOT 75 TIME 86 (of 500) ]
[ time 794 ] Run JOB 2 at PRIORITY 2 [ TICKS 5 ALLOT 75 TIME 85 (of 500) ]
[ time 795 ] Run JOB 2 at PRIORITY 2 [ TICKS 4 ALLOT 75 TIME 84 (of 500) ]
[ time 796 ] Run JOB 2 at PRIORITY 2 [ TICKS 3 ALLOT 75 TIME 83 (of 500) ]
[ time 797 ] Run JOB 2 at PRIORITY 2 [ TICKS 2 ALLOT 75 TIME 82 (of 500) ]
[ time 798 ] Run JOB 2 at PRIORITY 2 [ TICKS 1 ALLOT 75 TIME 81 (of 500) ]
[ time 799 ] Run JOB 2 at PRIORITY 2 [ TICKS 0 ALLOT 75 TIME 80 (of 500) ]
[ time 800 ] Run JOB 2 at PRIORITY 2 [ TICKS 9 ALLOT 74 TIME 79 (of 500) ]
[ time 801 ] Run JOB 2 at PRIORITY 2 [ TICKS 8 ALLOT 74 TIME 78 (of 500) ]
[ time 802 ] Run JOB 2 at PRIORITY 2 [ TICKS 7 ALLOT 74 TIME 77 (of 500) ]
[ time 803 ] Run JOB 2 at PRIORITY 2 [ TICKS 6 ALLOT 74 TIME 76 (of 500) ]
[ time 804 ] Run JOB 2 at PRIORITY 2 [ TICKS 5 ALLOT 74 TIME 75 (of 500) ]
[ time 805 ] Run JOB 2 at PRIORITY 2 [ TICKS 4 ALLOT 74 TIME 74 (of 500) ]
[ time 806 ] Run JOB 2 at PRIORITY 2 [ TICKS 3 ALLOT 74 TIME 73 (of 500) ]
[ time 807 ] Run JOB 2 at PRIORITY 2 [ TICKS 2 ALLOT 74 TIME 72 (of 500) ]
[ time 808 ] Run JOB 2 at PRIORITY 2 [ TICKS 1 ALLOT 74 TIME 71 (of 500) ]
[ time 809 ] Run JOB 2 at PRIORITY 2 [ TICKS 0 ALLOT 74 TIME 70 (of 500) ]
[ time 810 ] Run JOB 2 at PRIORITY 2 [ TICKS 9 ALLOT 73 TIME 69 (of 500) ]
[ time 811 ] Run JOB 2 at PRIORITY 2 [ TICKS 8 ALLOT 73 TIME 68 (of 500) ]
[ time 812 ] Run JOB 2 at PRIORITY 2 [ TICKS 7 ALLOT 73 TIME 67 (of 500) ]
[ time 813 ] Run JOB 2 at PRIORITY 2 [ TICKS 6 ALLOT 73 TIME 66 (of 500) ]
[ time 814 ] Run JOB 2 at PRIORITY 2 [ TICKS 5 ALLOT 73 TIME 65 (of 500) ]
[ time 815 ] Run JOB 2 at PRIORITY 2 [ TICKS 4 ALLOT 73 TIME 64 (of 500) ]
[ time 816 ] Run JOB 2 at PRIORITY 2 [ TICKS 3 ALLOT 73 TIME 63 (of 500) ]
[ time 817 ] Run JOB 2 at PRIORITY 2 [ TICKS 2 ALLOT 73 TIME 62 (of 500) ]
[ time 818 ] Run JOB 2 at PRIORITY 2 [ TICKS 1 ALLOT 73 TIME 61 (of 500) ]
[ time 819 ] Run JOB 2 at PRIORITY 2 [ TICKS 0 ALLOT 73 TIME 60 (of 500) ]
[ time 820 ] Run JOB 2 at PRIORITY 2 [ TICKS 9 ALLOT 72 TIME 59 (of 500) ]
[ time 821 ] Run JOB 2 at PRIORITY 2 [ TICKS 8 ALLOT 72 TIME 58 (of 500) ]
[ time 822 ] Run JOB 2 at PRIORITY 2 [ TICKS 7 ALLOT 72 TIME 57 (of 500) ]
[ time 823 ] Run JOB 2 at PRIORITY 2 [ TICKS 6 ALLOT 72 TIME 56 (of 500) ]
[ time 824 ] Run JOB 2 at PRIORITY 2 [ TICKS 5 ALLOT 72 TIME 55 (of 500) ]
[ time 825 ] Run JOB 2 at PRIORITY 2 [ TICKS 4 ALLOT 72 TIME 54 (of 500) ]
[ time 826 ] Run JOB 2 at PRIORITY 2 [ TICKS 3 ALLOT 72 TIME 53 (of 500) ]
[ time 827 ] Run JOB 2 at PRIORITY 2 [ TICKS 2 ALLOT 72 TIME 52 (of 500) ]
[ time 828 ] Run JOB 2 at PRIORITY 2 [ TICKS 1 ALLOT 72 TIME 51 (of 500) ]
[ time 829 ] Run JOB 2 at PRIORITY 2 [ TICKS 0 ALLOT 72 TIME 50 (of 500) ]
[ time 830 ] Run JOB 2 at PRIORITY 2 [ TICKS 9 ALLOT 71 TIME 49 (of 500) ]
[ time 831 ] Run JOB 2 at PRIORITY 2 [ TICKS 8 ALLOT 71 TIME 48 (of 500) ]
[ time 832 ] Run JOB 2 at PRIORITY 2 [ TICKS 7 ALLOT 71 TIME 47 (of 500) ]
[ time 833 ] Run JOB 2 at PRIORITY 2 [ TICKS 6 ALLOT 71 TIME 46 (of 500) ]
[ time 834 ] Run JOB 2 at PRIORITY 2 [ TICKS 5 ALLOT 71 TIME 45 (of 500) ]
[ time 835 ] Run JOB 2 at PRIORITY 2 [ TICKS 4 ALLOT 71 TIME 44 (of 500) ]
[ time 836 ] Run JOB 2 at PRIORITY 2 [ TICKS 3 ALLOT 71 TIME 43 (of 500) ]
[ time 837 ] Run JOB 2 at PRIORITY 2 [ TICKS 2 ALLOT 71 TIME 42 (of 500) ]
[ time 838 ] Run JOB 2 at PRIORITY 2 [ TICKS 1 ALLOT 71 TIME 41 (of 500) ]
[ time 839 ] Run JOB 2 at PRIORITY 2 [ TICKS 0 ALLOT 71 TIME 40 (of 500) ]
[ time 840 ] Run JOB 2 at PRIORITY 2 [ TICKS 9 ALLOT 70 TIME 39 (of 500) ]
[ time 841 ] Run JOB 2 at PRIORITY 2 [ TICKS 8 ALLOT 70 TIME 38 (of 500) ]
[ time 842 ] Run JOB 2 at PRIORITY 2 [ TICKS 7 ALLOT 70 TIME 37 (of 500) ]
[ time 843 ] Run JOB 2 at PRIORITY 2 [ TICKS 6 ALLOT 70 TIME 36 (of 500) ]
[ time 844 ] Run JOB 2 at PRIORITY 2 [ TICKS 5 ALLOT 70 TIME 35 (of 500) ]
[ time 845 ] Run JOB 2 at PRIORITY 2 [ TICKS 4 ALLOT 70 TIME 34 (of 500) ]
[ time 846 ] Run JOB 2 at PRIORITY 2 [ TICKS 3 ALLOT 70 TIME 33 (of 500) ]
[ time 847 ] Run JOB 2 at PRIORITY 2 [ TICKS 2 ALLOT 70 TIME 32 (of 500) ]
[ time 848 ] Run JOB 2 at PRIORITY 2 [ TICKS 1 ALLOT 70 TIME 31 (of 500) ]
[ time 849 ] Run JOB 2 at PRIORITY 2 [ TICKS 0 ALLOT 70 TIME 30 (of 500) ]
[ time 850 ] Run JOB 2 at PRIORITY 2 [ TICKS 9 ALLOT 69 TIME 29 (of 500) ]
[ time 851 ] Run JOB 2 at PRIORITY 2 [ TICKS 8 ALLOT 69 TIME 28 (of 500) ]
[ time 852 ] Run JOB 2 at PRIORITY 2 [ TICKS 7 ALLOT 69 TIME 27 (of 500) ]
[ time 853 ] Run JOB 2 at PRIORITY 2 [ TICKS 6 ALLOT 69 TIME 26 (of 500) ]
[ time 854 ] Run JOB 2 at PRIORITY 2 [ TICKS 5 ALLOT 69 TIME 25 (of 500) ]
[ time 855 ] Run JOB 2 at PRIORITY 2 [ TICKS 4 ALLOT 69 TIME 24 (of 500) ]
[ time 856 ] Run JOB 2 at PRIORITY 2 [ TICKS 3 ALLOT 69 TIME 23 (of 500) ]
[ time 857 ] Run JOB 2 at PRIORITY 2 [ TICKS 2 ALLOT 69 TIME 22 (of 500) ]
[ time 858 ] Run JOB 2 at PRIORITY 2 [ TICKS 1 ALLOT 69 TIME 21 (of 500) ]
[ time 859 ] Run JOB 2 at PRIORITY 2 [ TICKS 0 ALLOT 69 TIME 20 (of 500) ]
[ time 860 ] Run JOB 2 at PRIORITY 2 [ TICKS 9 ALLOT 68 TIME 19 (of 500) ]
[ time 861 ] Run JOB 2 at PRIORITY 2 [ TICKS 8 ALLOT 68 TIME 18 (of 500) ]
[ time 862 ] Run JOB 2 at PRIORITY 2 [ TICKS 7 ALLOT 68 TIME 17 (of 500) ]
[ time 863 ] Run JOB 2 at PRIORITY 2 [ TICKS 6 ALLOT 68 TIME 16 (of 500) ]
[ time 864 ] Run JOB 2 at PRIORITY 2 [ TICKS 5 ALLOT 68 TIME 15 (of 500) ]
[ time 865 ] Run JOB 2 at PRIORITY 2 [ TICKS 4 ALLOT 68 TIME 14 (of 500) ]
[ time 866 ] Run JOB 2 at PRIORITY 2 [ TICKS 3 ALLOT 68 TIME 13 (of 500) ]
[ time 867 ] Run JOB 2 at PRIORITY 2 [ TICKS 2 ALLOT 68 TIME 12 (of 500) ]
[ time 868 ] Run JOB 2 at PRIORITY 2 [ TICKS 1 ALLOT 68 TIME 11 (of 500) ]
[ time 869 ] Run JOB 2 at PRIORITY 2 [ TICKS 0 ALLOT 68 TIME 10 (of 500) ]
[ time 870 ] Run JOB 2 at PRIORITY 2 [ TICKS 9 ALLOT 67 TIME 9 (of 500) ]
[ time 871 ] Run JOB 2 at PRIORITY 2 [ TICKS 8 ALLOT 67 TIME 8 (of 500) ]
[ time 872 ] Run JOB 2 at PRIORITY 2 [ TICKS 7 ALLOT 67 TIME 7 (of 500) ]
[ time 873 ] Run JOB 2 at PRIORITY 2 [ TICKS 6 ALLOT 67 TIME 6 (of 500) ]
[ time 874 ] Run JOB 2 at PRIORITY 2 [ TICKS 5 ALLOT 67 TIME 5 (of 500) ]
[ time 875 ] Run JOB 2 at PRIORITY 2 [ TICKS 4 ALLOT 67 TIME 4 (of 500) ]
[ time 876 ] Run JOB 2 at PRIORITY 2 [ TICKS 3 ALLOT 67 TIME 3 (of 500) ]
[ time 877 ] Run JOB 2 at PRIORITY 2 [ TICKS 2 ALLOT 67 TIME 2 (of 500) ]
[ time 878 ] Run JOB 2 at PRIORITY 2 [ TICKS 1 ALLOT 67 TIME 1 (of 500) ]
[ time 879 ] Run JOB 2 at PRIORITY 2 [ TICKS 0 ALLOT 67 TIME 0 (of 500) ]
[ time 880 ] FINISHED JOB 2

Final statistics:
  Job  0: startTime   0 - response   0 - turnaround 520
  Job  1: startTime   0 - response  10 - turnaround 570
  Job  2: startTime   0 - response  20 - turnaround 880

  Avg  2: startTime n/a - response 10.00 - turnaround 656.67


